libs/cuda(3):ERROR:105: Unable to locate a modulefile for 'libs/cuda/11.7.0'
libs/cuDNN/8.1.0(16):ERROR:151: Module 'libs/cuDNN/8.1.0' depends on one of the module(s) 'libs/nvidia-hpc-sdk/23.1-nompi libs/nvidia-hpc-sdk/23.1-nocompiler libs/nvidia-hpc-sdk/23.1 libs/nvidia-hpc-sdk/22.3-nompi libs/nvidia-hpc-sdk/22.3-nocompiler libs/nvidia-hpc-sdk/22.3 libs/nvidia-hpc-sdk/21.5-nompi libs/nvidia-hpc-sdk/21.5-nocompiler libs/nvidia-hpc-sdk/21.5 libs/nvidia-hpc-sdk/21.3-nompi libs/nvidia-hpc-sdk/21.3-nocompiler libs/nvidia-hpc-sdk/21.3'
libs/cuDNN/8.1.0(16):ERROR:102: Tcl command execution failed: prereq  libs/cuda/11.2.0 libs/cuda/11.1.1 libs/cuda/11.0.3 libs/nvidia-hpc-sdk

[WARNING 04-18 20:24:03] ax.service.utils.with_db_settings_base: Ax currently requires a sqlalchemy version below 2.0. This will be addressed in a future release. Disabling SQL storage in Ax for now, if you would like to use SQL storage please install Ax with mysql extras via `pip install ax-platform[mysql]`.
2023-04-18 20:24:11,995	WARNING function_runner.py:598 -- Function checkpointing is disabled. This may result in unexpected behavior when using checkpointing features or certain schedulers. To enable, set the train function arguments to be `func(config, checkpoint_dir=None)`.
2023-04-18 20:24:12,334	INFO trial_runner.py:803 -- starting train_model_99452_00000
2023-04-18 20:24:18,094	INFO trial_runner.py:803 -- starting train_model_99452_00001
[2m[36m(func pid=81531)[0m /mnt/iusers01/ct01/t18155cb/.local/lib/python3.9/site-packages/torch/functional.py:504: UserWarning: torch.meshgrid: in an upcoming release, it will be required to pass the indexing argument. (Triggered internally at ../aten/src/ATen/native/TensorShape.cpp:3483.)
[2m[36m(func pid=81531)[0m   return _VF.meshgrid(tensors, **kwargs)  # type: ignore[attr-defined]
[2m[36m(func pid=81531)[0m /mnt/iusers01/ct01/t18155cb/.local/lib/python3.9/site-packages/torch/cuda/amp/grad_scaler.py:120: UserWarning: torch.cuda.amp.GradScaler is enabled, but CUDA is not available.  Disabling.
[2m[36m(func pid=81531)[0m   warnings.warn("torch.cuda.amp.GradScaler is enabled, but CUDA is not available.  Disabling.")
[2m[36m(func pid=81531)[0m /mnt/iusers01/ct01/t18155cb/.local/lib/python3.9/site-packages/torch/amp/autocast_mode.py:204: UserWarning: User provided device_type of 'cuda', but CUDA is not available. Disabling
[2m[36m(func pid=81531)[0m   warnings.warn('User provided device_type of \'cuda\', but CUDA is not available. Disabling')
2023-04-18 20:24:24,036	INFO trial_runner.py:803 -- starting train_model_99452_00002
[2m[36m(func pid=81625)[0m /mnt/iusers01/ct01/t18155cb/.local/lib/python3.9/site-packages/torch/functional.py:504: UserWarning: torch.meshgrid: in an upcoming release, it will be required to pass the indexing argument. (Triggered internally at ../aten/src/ATen/native/TensorShape.cpp:3483.)
[2m[36m(func pid=81625)[0m   return _VF.meshgrid(tensors, **kwargs)  # type: ignore[attr-defined]
[2m[36m(func pid=81625)[0m /mnt/iusers01/ct01/t18155cb/.local/lib/python3.9/site-packages/torch/cuda/amp/grad_scaler.py:120: UserWarning: torch.cuda.amp.GradScaler is enabled, but CUDA is not available.  Disabling.
[2m[36m(func pid=81625)[0m   warnings.warn("torch.cuda.amp.GradScaler is enabled, but CUDA is not available.  Disabling.")
[2m[36m(func pid=81625)[0m /mnt/iusers01/ct01/t18155cb/.local/lib/python3.9/site-packages/torch/amp/autocast_mode.py:204: UserWarning: User provided device_type of 'cuda', but CUDA is not available. Disabling
[2m[36m(func pid=81625)[0m   warnings.warn('User provided device_type of \'cuda\', but CUDA is not available. Disabling')
2023-04-18 20:24:31,191	INFO trial_runner.py:803 -- starting train_model_99452_00003
[2m[36m(func pid=81719)[0m /mnt/iusers01/ct01/t18155cb/.local/lib/python3.9/site-packages/torch/functional.py:504: UserWarning: torch.meshgrid: in an upcoming release, it will be required to pass the indexing argument. (Triggered internally at ../aten/src/ATen/native/TensorShape.cpp:3483.)
[2m[36m(func pid=81719)[0m   return _VF.meshgrid(tensors, **kwargs)  # type: ignore[attr-defined]
[2m[36m(func pid=81719)[0m /mnt/iusers01/ct01/t18155cb/.local/lib/python3.9/site-packages/torch/cuda/amp/grad_scaler.py:120: UserWarning: torch.cuda.amp.GradScaler is enabled, but CUDA is not available.  Disabling.
[2m[36m(func pid=81719)[0m   warnings.warn("torch.cuda.amp.GradScaler is enabled, but CUDA is not available.  Disabling.")
[2m[36m(func pid=81719)[0m /mnt/iusers01/ct01/t18155cb/.local/lib/python3.9/site-packages/torch/amp/autocast_mode.py:204: UserWarning: User provided device_type of 'cuda', but CUDA is not available. Disabling
[2m[36m(func pid=81719)[0m   warnings.warn('User provided device_type of \'cuda\', but CUDA is not available. Disabling')
[2m[36m(func pid=81801)[0m /mnt/iusers01/ct01/t18155cb/.local/lib/python3.9/site-packages/torch/functional.py:504: UserWarning: torch.meshgrid: in an upcoming release, it will be required to pass the indexing argument. (Triggered internally at ../aten/src/ATen/native/TensorShape.cpp:3483.)
[2m[36m(func pid=81801)[0m   return _VF.meshgrid(tensors, **kwargs)  # type: ignore[attr-defined]
[2m[36m(func pid=81801)[0m /mnt/iusers01/ct01/t18155cb/.local/lib/python3.9/site-packages/torch/cuda/amp/grad_scaler.py:120: UserWarning: torch.cuda.amp.GradScaler is enabled, but CUDA is not available.  Disabling.
[2m[36m(func pid=81801)[0m   warnings.warn("torch.cuda.amp.GradScaler is enabled, but CUDA is not available.  Disabling.")
[2m[36m(func pid=81801)[0m /mnt/iusers01/ct01/t18155cb/.local/lib/python3.9/site-packages/torch/amp/autocast_mode.py:204: UserWarning: User provided device_type of 'cuda', but CUDA is not available. Disabling
[2m[36m(func pid=81801)[0m   warnings.warn('User provided device_type of \'cuda\', but CUDA is not available. Disabling')
[2m[36m(func pid=81531)[0m 2023-04-18 20:54:15,211	ERROR function_runner.py:281 -- Runner Thread raised error.
[2m[36m(func pid=81531)[0m Traceback (most recent call last):
[2m[36m(func pid=81531)[0m   File "/mnt/iusers01/ct01/t18155cb/.local/lib/python3.9/site-packages/ray/tune/function_runner.py", line 272, in run
[2m[36m(func pid=81531)[0m     self._entrypoint()
[2m[36m(func pid=81531)[0m   File "/mnt/iusers01/ct01/t18155cb/.local/lib/python3.9/site-packages/ray/tune/function_runner.py", line 348, in entrypoint
[2m[36m(func pid=81531)[0m     return self._trainable_func(
[2m[36m(func pid=81531)[0m   File "/mnt/iusers01/ct01/t18155cb/.local/lib/python3.9/site-packages/ray/util/tracing/tracing_helper.py", line 462, in _resume_span
[2m[36m(func pid=81531)[0m     return method(self, *_args, **_kwargs)
[2m[36m(func pid=81531)[0m   File "/mnt/iusers01/ct01/t18155cb/.local/lib/python3.9/site-packages/ray/tune/function_runner.py", line 640, in _trainable_func
[2m[36m(func pid=81531)[0m     output = fn()
[2m[36m(func pid=81531)[0m   File "/net/scratch2/t18155cb/SwinVisonTranslation_mIHC/Ray_tune_hyp.py", line 90, in train_model
[2m[36m(func pid=81531)[0m     outputs = model(inputs)
[2m[36m(func pid=81531)[0m   File "/mnt/iusers01/ct01/t18155cb/.local/lib/python3.9/site-packages/torch/nn/modules/module.py", line 1501, in _call_impl
[2m[36m(func pid=81531)[0m     return forward_call(*args, **kwargs)
[2m[36m(func pid=81531)[0m   File "/net/scratch2/t18155cb/SwinVisonTranslation_mIHC/SwinVisionTranformer.py", line 106, in forward
[2m[36m(func pid=81531)[0m     x = x + x_skip
[2m[36m(func pid=81531)[0m RuntimeError: The size of tensor a (65536) must match the size of tensor b (64) at non-singleton dimension 3
[2m[36m(func pid=81531)[0m Exception in thread Thread-3:
[2m[36m(func pid=81531)[0m Traceback (most recent call last):
[2m[36m(func pid=81531)[0m   File "/opt/apps/apps/python/miniconda3/4.10.3/lib/python3.9/threading.py", line 954, in _bootstrap_inner
[2m[36m(func pid=81531)[0m     self.run()
[2m[36m(func pid=81531)[0m   File "/mnt/iusers01/ct01/t18155cb/.local/lib/python3.9/site-packages/ray/tune/function_runner.py", line 298, in run
[2m[36m(func pid=81531)[0m     raise e
[2m[36m(func pid=81531)[0m   File "/mnt/iusers01/ct01/t18155cb/.local/lib/python3.9/site-packages/ray/tune/function_runner.py", line 272, in run
[2m[36m(func pid=81531)[0m     self._entrypoint()
[2m[36m(func pid=81531)[0m   File "/mnt/iusers01/ct01/t18155cb/.local/lib/python3.9/site-packages/ray/tune/function_runner.py", line 348, in entrypoint
[2m[36m(func pid=81531)[0m     return self._trainable_func(
[2m[36m(func pid=81531)[0m   File "/mnt/iusers01/ct01/t18155cb/.local/lib/python3.9/site-packages/ray/util/tracing/tracing_helper.py", line 462, in _resume_span
[2m[36m(func pid=81531)[0m     return method(self, *_args, **_kwargs)
[2m[36m(func pid=81531)[0m   File "/mnt/iusers01/ct01/t18155cb/.local/lib/python3.9/site-packages/ray/tune/function_runner.py", line 640, in _trainable_func
[2m[36m(func pid=81531)[0m     output = fn()
[2m[36m(func pid=81531)[0m   File "/net/scratch2/t18155cb/SwinVisonTranslation_mIHC/Ray_tune_hyp.py", line 90, in train_model
[2m[36m(func pid=81531)[0m     outputs = model(inputs)
[2m[36m(func pid=81531)[0m   File "/mnt/iusers01/ct01/t18155cb/.local/lib/python3.9/site-packages/torch/nn/modules/module.py", line 1501, in _call_impl
[2m[36m(func pid=81531)[0m     return forward_call(*args, **kwargs)
[2m[36m(func pid=81531)[0m   File "/net/scratch2/t18155cb/SwinVisonTranslation_mIHC/SwinVisionTranformer.py", line 106, in forward
[2m[36m(func pid=81531)[0m     x = x + x_skip
[2m[36m(func pid=81531)[0m RuntimeError: The size of tensor a (65536) must match the size of tensor b (64) at non-singleton dimension 3
2023-04-18 20:54:18,968	ERROR trial_runner.py:876 -- Trial train_model_99452_00000: Error processing event.
NoneType: None
2023-04-18 20:54:19,138	INFO trial_runner.py:803 -- starting train_model_99452_00004
[2m[36m(func pid=85380)[0m /mnt/iusers01/ct01/t18155cb/.local/lib/python3.9/site-packages/torch/functional.py:504: UserWarning: torch.meshgrid: in an upcoming release, it will be required to pass the indexing argument. (Triggered internally at ../aten/src/ATen/native/TensorShape.cpp:3483.)
[2m[36m(func pid=85380)[0m   return _VF.meshgrid(tensors, **kwargs)  # type: ignore[attr-defined]
[2m[36m(func pid=85380)[0m /mnt/iusers01/ct01/t18155cb/.local/lib/python3.9/site-packages/torch/cuda/amp/grad_scaler.py:120: UserWarning: torch.cuda.amp.GradScaler is enabled, but CUDA is not available.  Disabling.
[2m[36m(func pid=85380)[0m   warnings.warn("torch.cuda.amp.GradScaler is enabled, but CUDA is not available.  Disabling.")
[2m[36m(func pid=85380)[0m /mnt/iusers01/ct01/t18155cb/.local/lib/python3.9/site-packages/torch/amp/autocast_mode.py:204: UserWarning: User provided device_type of 'cuda', but CUDA is not available. Disabling
[2m[36m(func pid=85380)[0m   warnings.warn('User provided device_type of \'cuda\', but CUDA is not available. Disabling')
[2m[36m(func pid=81801)[0m 2023-04-18 21:21:00,866	ERROR function_runner.py:281 -- Runner Thread raised error.
[2m[36m(func pid=81801)[0m Traceback (most recent call last):
[2m[36m(func pid=81801)[0m   File "/mnt/iusers01/ct01/t18155cb/.local/lib/python3.9/site-packages/ray/tune/function_runner.py", line 272, in run
[2m[36m(func pid=81801)[0m     self._entrypoint()
[2m[36m(func pid=81801)[0m   File "/mnt/iusers01/ct01/t18155cb/.local/lib/python3.9/site-packages/ray/tune/function_runner.py", line 348, in entrypoint
[2m[36m(func pid=81801)[0m     return self._trainable_func(
[2m[36m(func pid=81801)[0m   File "/mnt/iusers01/ct01/t18155cb/.local/lib/python3.9/site-packages/ray/util/tracing/tracing_helper.py", line 462, in _resume_span
[2m[36m(func pid=81801)[0m     return method(self, *_args, **_kwargs)
[2m[36m(func pid=81801)[0m   File "/mnt/iusers01/ct01/t18155cb/.local/lib/python3.9/site-packages/ray/tune/function_runner.py", line 640, in _trainable_func
[2m[36m(func pid=81801)[0m     output = fn()
[2m[36m(func pid=81801)[0m   File "/net/scratch2/t18155cb/SwinVisonTranslation_mIHC/Ray_tune_hyp.py", line 90, in train_model
[2m[36m(func pid=81801)[0m     outputs = model(inputs)
[2m[36m(func pid=81801)[0m   File "/mnt/iusers01/ct01/t18155cb/.local/lib/python3.9/site-packages/torch/nn/modules/module.py", line 1501, in _call_impl
[2m[36m(func pid=81801)[0m     return forward_call(*args, **kwargs)
[2m[36m(func pid=81801)[0m   File "/net/scratch2/t18155cb/SwinVisonTranslation_mIHC/SwinVisionTranformer.py", line 106, in forward
[2m[36m(func pid=81801)[0m     x = x + x_skip
[2m[36m(func pid=81801)[0m RuntimeError: The size of tensor a (65536) must match the size of tensor b (64) at non-singleton dimension 3
[2m[36m(func pid=81801)[0m Exception in thread Thread-3:
[2m[36m(func pid=81801)[0m Traceback (most recent call last):
[2m[36m(func pid=81801)[0m   File "/opt/apps/apps/python/miniconda3/4.10.3/lib/python3.9/threading.py", line 954, in _bootstrap_inner
[2m[36m(func pid=81801)[0m     self.run()
[2m[36m(func pid=81801)[0m   File "/mnt/iusers01/ct01/t18155cb/.local/lib/python3.9/site-packages/ray/tune/function_runner.py", line 298, in run
[2m[36m(func pid=81801)[0m     raise e
[2m[36m(func pid=81801)[0m   File "/mnt/iusers01/ct01/t18155cb/.local/lib/python3.9/site-packages/ray/tune/function_runner.py", line 272, in run
[2m[36m(func pid=81801)[0m     self._entrypoint()
[2m[36m(func pid=81801)[0m   File "/mnt/iusers01/ct01/t18155cb/.local/lib/python3.9/site-packages/ray/tune/function_runner.py", line 348, in entrypoint
[2m[36m(func pid=81801)[0m     return self._trainable_func(
[2m[36m(func pid=81801)[0m   File "/mnt/iusers01/ct01/t18155cb/.local/lib/python3.9/site-packages/ray/util/tracing/tracing_helper.py", line 462, in _resume_span
[2m[36m(func pid=81801)[0m     return method(self, *_args, **_kwargs)
[2m[36m(func pid=81801)[0m   File "/mnt/iusers01/ct01/t18155cb/.local/lib/python3.9/site-packages/ray/tune/function_runner.py", line 640, in _trainable_func
[2m[36m(func pid=81801)[0m     output = fn()
[2m[36m(func pid=81801)[0m   File "/net/scratch2/t18155cb/SwinVisonTranslation_mIHC/Ray_tune_hyp.py", line 90, in train_model
[2m[36m(func pid=81801)[0m     outputs = model(inputs)
[2m[36m(func pid=81801)[0m   File "/mnt/iusers01/ct01/t18155cb/.local/lib/python3.9/site-packages/torch/nn/modules/module.py", line 1501, in _call_impl
[2m[36m(func pid=81801)[0m     return forward_call(*args, **kwargs)
[2m[36m(func pid=81801)[0m   File "/net/scratch2/t18155cb/SwinVisonTranslation_mIHC/SwinVisionTranformer.py", line 106, in forward
[2m[36m(func pid=81801)[0m     x = x + x_skip
[2m[36m(func pid=81801)[0m RuntimeError: The size of tensor a (65536) must match the size of tensor b (64) at non-singleton dimension 3
[2m[36m(func pid=85380)[0m 2023-04-18 21:21:00,731	ERROR function_runner.py:281 -- Runner Thread raised error.
[2m[36m(func pid=85380)[0m Traceback (most recent call last):
[2m[36m(func pid=85380)[0m   File "/mnt/iusers01/ct01/t18155cb/.local/lib/python3.9/site-packages/ray/tune/function_runner.py", line 272, in run
[2m[36m(func pid=85380)[0m     self._entrypoint()
[2m[36m(func pid=85380)[0m   File "/mnt/iusers01/ct01/t18155cb/.local/lib/python3.9/site-packages/ray/tune/function_runner.py", line 348, in entrypoint
[2m[36m(func pid=85380)[0m     return self._trainable_func(
[2m[36m(func pid=85380)[0m   File "/mnt/iusers01/ct01/t18155cb/.local/lib/python3.9/site-packages/ray/util/tracing/tracing_helper.py", line 462, in _resume_span
[2m[36m(func pid=85380)[0m     return method(self, *_args, **_kwargs)
[2m[36m(func pid=85380)[0m   File "/mnt/iusers01/ct01/t18155cb/.local/lib/python3.9/site-packages/ray/tune/function_runner.py", line 640, in _trainable_func
[2m[36m(func pid=85380)[0m     output = fn()
[2m[36m(func pid=85380)[0m   File "/net/scratch2/t18155cb/SwinVisonTranslation_mIHC/Ray_tune_hyp.py", line 90, in train_model
[2m[36m(func pid=85380)[0m     outputs = model(inputs)
[2m[36m(func pid=85380)[0m   File "/mnt/iusers01/ct01/t18155cb/.local/lib/python3.9/site-packages/torch/nn/modules/module.py", line 1501, in _call_impl
[2m[36m(func pid=85380)[0m     return forward_call(*args, **kwargs)
[2m[36m(func pid=85380)[0m   File "/net/scratch2/t18155cb/SwinVisonTranslation_mIHC/SwinVisionTranformer.py", line 105, in forward
[2m[36m(func pid=85380)[0m     x = self.decoder(x)
[2m[36m(func pid=85380)[0m   File "/mnt/iusers01/ct01/t18155cb/.local/lib/python3.9/site-packages/torch/nn/modules/module.py", line 1501, in _call_impl
[2m[36m(func pid=85380)[0m     return forward_call(*args, **kwargs)
[2m[36m(func pid=85380)[0m   File "/mnt/iusers01/ct01/t18155cb/.local/lib/python3.9/site-packages/torch/nn/modules/container.py", line 217, in forward
[2m[36m(func pid=85380)[0m     input = module(input)
[2m[36m(func pid=85380)[0m   File "/mnt/iusers01/ct01/t18155cb/.local/lib/python3.9/site-packages/torch/nn/modules/module.py", line 1501, in _call_impl
[2m[36m(func pid=85380)[0m     return forward_call(*args, **kwargs)
[2m[36m(func pid=85380)[0m   File "/mnt/iusers01/ct01/t18155cb/.local/lib/python3.9/site-packages/torch/nn/modules/upsampling.py", line 156, in forward
[2m[36m(func pid=85380)[0m     return F.interpolate(input, self.size, self.scale_factor, self.mode, self.align_corners,
[2m[36m(func pid=85380)[0m   File "/mnt/iusers01/ct01/t18155cb/.local/lib/python3.9/site-packages/torch/nn/functional.py", line 3959, in interpolate
[2m[36m(func pid=85380)[0m     return torch._C._nn.upsample_bilinear2d(input, output_size, align_corners, scale_factors)
[2m[36m(func pid=85380)[0m RuntimeError: [enforce fail at alloc_cpu.cpp:75] err == 0. DefaultCPUAllocator: can't allocate memory: you tried to allocate 68719476736 bytes. Error code 12 (Cannot allocate memory)
[2m[36m(func pid=85380)[0m Exception in thread Thread-3:
[2m[36m(func pid=85380)[0m Traceback (most recent call last):
[2m[36m(func pid=85380)[0m   File "/opt/apps/apps/python/miniconda3/4.10.3/lib/python3.9/threading.py", line 954, in _bootstrap_inner
[2m[36m(func pid=85380)[0m     self.run()
[2m[36m(func pid=85380)[0m   File "/mnt/iusers01/ct01/t18155cb/.local/lib/python3.9/site-packages/ray/tune/function_runner.py", line 298, in run
[2m[36m(func pid=85380)[0m     raise e
[2m[36m(func pid=85380)[0m   File "/mnt/iusers01/ct01/t18155cb/.local/lib/python3.9/site-packages/ray/tune/function_runner.py", line 272, in run
[2m[36m(func pid=85380)[0m     self._entrypoint()
[2m[36m(func pid=85380)[0m   File "/mnt/iusers01/ct01/t18155cb/.local/lib/python3.9/site-packages/ray/tune/function_runner.py", line 348, in entrypoint
[2m[36m(func pid=85380)[0m     return self._trainable_func(
[2m[36m(func pid=85380)[0m   File "/mnt/iusers01/ct01/t18155cb/.local/lib/python3.9/site-packages/ray/util/tracing/tracing_helper.py", line 462, in _resume_span
[2m[36m(func pid=85380)[0m     return method(self, *_args, **_kwargs)
[2m[36m(func pid=85380)[0m   File "/mnt/iusers01/ct01/t18155cb/.local/lib/python3.9/site-packages/ray/tune/function_runner.py", line 640, in _trainable_func
[2m[36m(func pid=85380)[0m     output = fn()
[2m[36m(func pid=85380)[0m   File "/net/scratch2/t18155cb/SwinVisonTranslation_mIHC/Ray_tune_hyp.py", line 90, in train_model
[2m[36m(func pid=85380)[0m     outputs = model(inputs)
[2m[36m(func pid=85380)[0m   File "/mnt/iusers01/ct01/t18155cb/.local/lib/python3.9/site-packages/torch/nn/modules/module.py", line 1501, in _call_impl
[2m[36m(func pid=85380)[0m     return forward_call(*args, **kwargs)
[2m[36m(func pid=85380)[0m   File "/net/scratch2/t18155cb/SwinVisonTranslation_mIHC/SwinVisionTranformer.py", line 105, in forward
[2m[36m(func pid=85380)[0m     x = self.decoder(x)
[2m[36m(func pid=85380)[0m   File "/mnt/iusers01/ct01/t18155cb/.local/lib/python3.9/site-packages/torch/nn/modules/module.py", line 1501, in _call_impl
[2m[36m(func pid=85380)[0m     return forward_call(*args, **kwargs)
[2m[36m(func pid=85380)[0m   File "/mnt/iusers01/ct01/t18155cb/.local/lib/python3.9/site-packages/torch/nn/modules/container.py", line 217, in forward
[2m[36m(func pid=85380)[0m     input = module(input)
[2m[36m(func pid=85380)[0m   File "/mnt/iusers01/ct01/t18155cb/.local/lib/python3.9/site-packages/torch/nn/modules/module.py", line 1501, in _call_impl
[2m[36m(func pid=85380)[0m     return forward_call(*args, **kwargs)
[2m[36m(func pid=85380)[0m   File "/mnt/iusers01/ct01/t18155cb/.local/lib/python3.9/site-packages/torch/nn/modules/upsampling.py", line 156, in forward
[2m[36m(func pid=85380)[0m     return F.interpolate(input, self.size, self.scale_factor, self.mode, self.align_corners,
[2m[36m(func pid=85380)[0m   File "/mnt/iusers01/ct01/t18155cb/.local/lib/python3.9/site-packages/torch/nn/functional.py", line 3959, in interpolate
[2m[36m(func pid=85380)[0m     return torch._C._nn.upsample_bilinear2d(input, output_size, align_corners, scale_factors)
[2m[36m(func pid=85380)[0m RuntimeError: [enforce fail at alloc_cpu.cpp:75] err == 0. DefaultCPUAllocator: can't allocate memory: you tried to allocate 68719476736 bytes. Error code 12 (Cannot allocate memory)
2023-04-18 21:21:02,436	ERROR trial_runner.py:876 -- Trial train_model_99452_00004: Error processing event.
NoneType: None
2023-04-18 21:21:02,788	INFO trial_runner.py:803 -- starting train_model_99452_00005
2023-04-18 21:21:46,656	ERROR trial_runner.py:876 -- Trial train_model_99452_00003: Error processing event.
NoneType: None
2023-04-18 21:21:46,791	INFO trial_runner.py:803 -- starting train_model_99452_00006
[2m[36m(func pid=88838)[0m /mnt/iusers01/ct01/t18155cb/.local/lib/python3.9/site-packages/torch/functional.py:504: UserWarning: torch.meshgrid: in an upcoming release, it will be required to pass the indexing argument. (Triggered internally at ../aten/src/ATen/native/TensorShape.cpp:3483.)
[2m[36m(func pid=88838)[0m   return _VF.meshgrid(tensors, **kwargs)  # type: ignore[attr-defined]
[2m[36m(func pid=88838)[0m /mnt/iusers01/ct01/t18155cb/.local/lib/python3.9/site-packages/torch/cuda/amp/grad_scaler.py:120: UserWarning: torch.cuda.amp.GradScaler is enabled, but CUDA is not available.  Disabling.
[2m[36m(func pid=88838)[0m   warnings.warn("torch.cuda.amp.GradScaler is enabled, but CUDA is not available.  Disabling.")
[2m[36m(func pid=88838)[0m /mnt/iusers01/ct01/t18155cb/.local/lib/python3.9/site-packages/torch/amp/autocast_mode.py:204: UserWarning: User provided device_type of 'cuda', but CUDA is not available. Disabling
[2m[36m(func pid=88838)[0m   warnings.warn('User provided device_type of \'cuda\', but CUDA is not available. Disabling')
[2m[36m(func pid=88999)[0m /mnt/iusers01/ct01/t18155cb/.local/lib/python3.9/site-packages/torch/functional.py:504: UserWarning: torch.meshgrid: in an upcoming release, it will be required to pass the indexing argument. (Triggered internally at ../aten/src/ATen/native/TensorShape.cpp:3483.)
[2m[36m(func pid=88999)[0m   return _VF.meshgrid(tensors, **kwargs)  # type: ignore[attr-defined]
[2m[36m(func pid=88999)[0m /mnt/iusers01/ct01/t18155cb/.local/lib/python3.9/site-packages/torch/cuda/amp/grad_scaler.py:120: UserWarning: torch.cuda.amp.GradScaler is enabled, but CUDA is not available.  Disabling.
[2m[36m(func pid=88999)[0m   warnings.warn("torch.cuda.amp.GradScaler is enabled, but CUDA is not available.  Disabling.")
[2m[36m(func pid=88999)[0m /mnt/iusers01/ct01/t18155cb/.local/lib/python3.9/site-packages/torch/amp/autocast_mode.py:204: UserWarning: User provided device_type of 'cuda', but CUDA is not available. Disabling
[2m[36m(func pid=88999)[0m   warnings.warn('User provided device_type of \'cuda\', but CUDA is not available. Disabling')
[2m[36m(func pid=88999)[0m 2023-04-18 21:52:51,213	ERROR function_runner.py:281 -- Runner Thread raised error.
[2m[36m(func pid=88999)[0m Traceback (most recent call last):
[2m[36m(func pid=88999)[0m   File "/mnt/iusers01/ct01/t18155cb/.local/lib/python3.9/site-packages/ray/tune/function_runner.py", line 272, in run
[2m[36m(func pid=88999)[0m     self._entrypoint()
[2m[36m(func pid=88999)[0m   File "/mnt/iusers01/ct01/t18155cb/.local/lib/python3.9/site-packages/ray/tune/function_runner.py", line 348, in entrypoint
[2m[36m(func pid=88999)[0m     return self._trainable_func(
[2m[36m(func pid=88999)[0m   File "/mnt/iusers01/ct01/t18155cb/.local/lib/python3.9/site-packages/ray/util/tracing/tracing_helper.py", line 462, in _resume_span
[2m[36m(func pid=88999)[0m     return method(self, *_args, **_kwargs)
[2m[36m(func pid=88999)[0m   File "/mnt/iusers01/ct01/t18155cb/.local/lib/python3.9/site-packages/ray/tune/function_runner.py", line 640, in _trainable_func
[2m[36m(func pid=88999)[0m     output = fn()
[2m[36m(func pid=88999)[0m   File "/net/scratch2/t18155cb/SwinVisonTranslation_mIHC/Ray_tune_hyp.py", line 90, in train_model
[2m[36m(func pid=88999)[0m     outputs = model(inputs)
[2m[36m(func pid=88999)[0m   File "/mnt/iusers01/ct01/t18155cb/.local/lib/python3.9/site-packages/torch/nn/modules/module.py", line 1501, in _call_impl
[2m[36m(func pid=88999)[0m     return forward_call(*args, **kwargs)
[2m[36m(func pid=88999)[0m   File "/net/scratch2/t18155cb/SwinVisonTranslation_mIHC/SwinVisionTranformer.py", line 106, in forward
[2m[36m(func pid=88999)[0m     x = x + x_skip
[2m[36m(func pid=88999)[0m RuntimeError: The size of tensor a (65536) must match the size of tensor b (64) at non-singleton dimension 3
[2m[36m(func pid=88999)[0m Exception in thread Thread-3:
[2m[36m(func pid=88999)[0m Traceback (most recent call last):
[2m[36m(func pid=88999)[0m   File "/opt/apps/apps/python/miniconda3/4.10.3/lib/python3.9/threading.py", line 954, in _bootstrap_inner
[2m[36m(func pid=88999)[0m     self.run()
[2m[36m(func pid=88999)[0m   File "/mnt/iusers01/ct01/t18155cb/.local/lib/python3.9/site-packages/ray/tune/function_runner.py", line 298, in run
[2m[36m(func pid=88999)[0m     raise e
[2m[36m(func pid=88999)[0m   File "/mnt/iusers01/ct01/t18155cb/.local/lib/python3.9/site-packages/ray/tune/function_runner.py", line 272, in run
[2m[36m(func pid=88999)[0m     self._entrypoint()
[2m[36m(func pid=88999)[0m   File "/mnt/iusers01/ct01/t18155cb/.local/lib/python3.9/site-packages/ray/tune/function_runner.py", line 348, in entrypoint
[2m[36m(func pid=88999)[0m     return self._trainable_func(
[2m[36m(func pid=88999)[0m   File "/mnt/iusers01/ct01/t18155cb/.local/lib/python3.9/site-packages/ray/util/tracing/tracing_helper.py", line 462, in _resume_span
[2m[36m(func pid=88999)[0m     return method(self, *_args, **_kwargs)
[2m[36m(func pid=88999)[0m   File "/mnt/iusers01/ct01/t18155cb/.local/lib/python3.9/site-packages/ray/tune/function_runner.py", line 640, in _trainable_func
[2m[36m(func pid=88999)[0m     output = fn()
[2m[36m(func pid=88999)[0m   File "/net/scratch2/t18155cb/SwinVisonTranslation_mIHC/Ray_tune_hyp.py", line 90, in train_model
[2m[36m(func pid=88999)[0m     outputs = model(inputs)
[2m[36m(func pid=88999)[0m   File "/mnt/iusers01/ct01/t18155cb/.local/lib/python3.9/site-packages/torch/nn/modules/module.py", line 1501, in _call_impl
[2m[36m(func pid=88999)[0m     return forward_call(*args, **kwargs)
[2m[36m(func pid=88999)[0m   File "/net/scratch2/t18155cb/SwinVisonTranslation_mIHC/SwinVisionTranformer.py", line 106, in forward
[2m[36m(func pid=88999)[0m     x = x + x_skip
[2m[36m(func pid=88999)[0m RuntimeError: The size of tensor a (65536) must match the size of tensor b (64) at non-singleton dimension 3
2023-04-18 21:52:57,864	ERROR trial_runner.py:876 -- Trial train_model_99452_00006: Error processing event.
NoneType: None
2023-04-18 21:52:58,013	INFO trial_runner.py:803 -- starting train_model_99452_00007
[2m[36m(func pid=92729)[0m /mnt/iusers01/ct01/t18155cb/.local/lib/python3.9/site-packages/torch/functional.py:504: UserWarning: torch.meshgrid: in an upcoming release, it will be required to pass the indexing argument. (Triggered internally at ../aten/src/ATen/native/TensorShape.cpp:3483.)
[2m[36m(func pid=92729)[0m   return _VF.meshgrid(tensors, **kwargs)  # type: ignore[attr-defined]
[2m[36m(func pid=92729)[0m /mnt/iusers01/ct01/t18155cb/.local/lib/python3.9/site-packages/torch/cuda/amp/grad_scaler.py:120: UserWarning: torch.cuda.amp.GradScaler is enabled, but CUDA is not available.  Disabling.
[2m[36m(func pid=92729)[0m   warnings.warn("torch.cuda.amp.GradScaler is enabled, but CUDA is not available.  Disabling.")
[2m[36m(func pid=92729)[0m /mnt/iusers01/ct01/t18155cb/.local/lib/python3.9/site-packages/torch/amp/autocast_mode.py:204: UserWarning: User provided device_type of 'cuda', but CUDA is not available. Disabling
[2m[36m(func pid=92729)[0m   warnings.warn('User provided device_type of \'cuda\', but CUDA is not available. Disabling')
[2m[36m(func pid=81719)[0m 2023-04-18 22:06:43,330	ERROR function_runner.py:281 -- Runner Thread raised error.
[2m[36m(func pid=81719)[0m Traceback (most recent call last):
[2m[36m(func pid=81719)[0m   File "/mnt/iusers01/ct01/t18155cb/.local/lib/python3.9/site-packages/ray/tune/function_runner.py", line 272, in run
[2m[36m(func pid=81719)[0m     self._entrypoint()
[2m[36m(func pid=81719)[0m   File "/mnt/iusers01/ct01/t18155cb/.local/lib/python3.9/site-packages/ray/tune/function_runner.py", line 348, in entrypoint
[2m[36m(func pid=81719)[0m     return self._trainable_func(
[2m[36m(func pid=81719)[0m   File "/mnt/iusers01/ct01/t18155cb/.local/lib/python3.9/site-packages/ray/util/tracing/tracing_helper.py", line 462, in _resume_span
[2m[36m(func pid=81719)[0m     return method(self, *_args, **_kwargs)
[2m[36m(func pid=81719)[0m   File "/mnt/iusers01/ct01/t18155cb/.local/lib/python3.9/site-packages/ray/tune/function_runner.py", line 640, in _trainable_func
[2m[36m(func pid=81719)[0m     output = fn()
[2m[36m(func pid=81719)[0m   File "/net/scratch2/t18155cb/SwinVisonTranslation_mIHC/Ray_tune_hyp.py", line 90, in train_model
[2m[36m(func pid=81719)[0m     outputs = model(inputs)
[2m[36m(func pid=81719)[0m   File "/mnt/iusers01/ct01/t18155cb/.local/lib/python3.9/site-packages/torch/nn/modules/module.py", line 1501, in _call_impl
[2m[36m(func pid=81719)[0m     return forward_call(*args, **kwargs)
[2m[36m(func pid=81719)[0m   File "/net/scratch2/t18155cb/SwinVisonTranslation_mIHC/SwinVisionTranformer.py", line 105, in forward
[2m[36m(func pid=81719)[0m     x = self.decoder(x)
[2m[36m(func pid=81719)[0m   File "/mnt/iusers01/ct01/t18155cb/.local/lib/python3.9/site-packages/torch/nn/modules/module.py", line 1501, in _call_impl
[2m[36m(func pid=81719)[0m     return forward_call(*args, **kwargs)
[2m[36m(func pid=81719)[0m   File "/mnt/iusers01/ct01/t18155cb/.local/lib/python3.9/site-packages/torch/nn/modules/container.py", line 217, in forward
[2m[36m(func pid=81719)[0m     input = module(input)
[2m[36m(func pid=81719)[0m   File "/mnt/iusers01/ct01/t18155cb/.local/lib/python3.9/site-packages/torch/nn/modules/module.py", line 1501, in _call_impl
[2m[36m(func pid=81719)[0m     return forward_call(*args, **kwargs)
[2m[36m(func pid=81719)[0m   File "/mnt/iusers01/ct01/t18155cb/.local/lib/python3.9/site-packages/torch/nn/modules/upsampling.py", line 156, in forward
[2m[36m(func pid=81719)[0m     return F.interpolate(input, self.size, self.scale_factor, self.mode, self.align_corners,
[2m[36m(func pid=81719)[0m   File "/mnt/iusers01/ct01/t18155cb/.local/lib/python3.9/site-packages/torch/nn/functional.py", line 3959, in interpolate
[2m[36m(func pid=81719)[0m     return torch._C._nn.upsample_bilinear2d(input, output_size, align_corners, scale_factors)
[2m[36m(func pid=81719)[0m RuntimeError: [enforce fail at alloc_cpu.cpp:75] err == 0. DefaultCPUAllocator: can't allocate memory: you tried to allocate 274877906944 bytes. Error code 12 (Cannot allocate memory)
[2m[36m(func pid=81719)[0m Exception in thread Thread-3:
[2m[36m(func pid=81719)[0m Traceback (most recent call last):
[2m[36m(func pid=81719)[0m   File "/opt/apps/apps/python/miniconda3/4.10.3/lib/python3.9/threading.py", line 954, in _bootstrap_inner
[2m[36m(func pid=81719)[0m     self.run()
[2m[36m(func pid=81719)[0m   File "/mnt/iusers01/ct01/t18155cb/.local/lib/python3.9/site-packages/ray/tune/function_runner.py", line 298, in run
[2m[36m(func pid=81719)[0m     raise e
[2m[36m(func pid=81719)[0m   File "/mnt/iusers01/ct01/t18155cb/.local/lib/python3.9/site-packages/ray/tune/function_runner.py", line 272, in run
[2m[36m(func pid=81719)[0m     self._entrypoint()
[2m[36m(func pid=81719)[0m   File "/mnt/iusers01/ct01/t18155cb/.local/lib/python3.9/site-packages/ray/tune/function_runner.py", line 348, in entrypoint
[2m[36m(func pid=81719)[0m     return self._trainable_func(
[2m[36m(func pid=81719)[0m   File "/mnt/iusers01/ct01/t18155cb/.local/lib/python3.9/site-packages/ray/util/tracing/tracing_helper.py", line 462, in _resume_span
[2m[36m(func pid=81719)[0m     return method(self, *_args, **_kwargs)
[2m[36m(func pid=81719)[0m   File "/mnt/iusers01/ct01/t18155cb/.local/lib/python3.9/site-packages/ray/tune/function_runner.py", line 640, in _trainable_func
[2m[36m(func pid=81719)[0m     output = fn()
[2m[36m(func pid=81719)[0m   File "/net/scratch2/t18155cb/SwinVisonTranslation_mIHC/Ray_tune_hyp.py", line 90, in train_model
[2m[36m(func pid=81719)[0m     outputs = model(inputs)
[2m[36m(func pid=81719)[0m   File "/mnt/iusers01/ct01/t18155cb/.local/lib/python3.9/site-packages/torch/nn/modules/module.py", line 1501, in _call_impl
[2m[36m(func pid=81719)[0m     return forward_call(*args, **kwargs)
[2m[36m(func pid=81719)[0m   File "/net/scratch2/t18155cb/SwinVisonTranslation_mIHC/SwinVisionTranformer.py", line 105, in forward
[2m[36m(func pid=81719)[0m     x = self.decoder(x)
[2m[36m(func pid=81719)[0m   File "/mnt/iusers01/ct01/t18155cb/.local/lib/python3.9/site-packages/torch/nn/modules/module.py", line 1501, in _call_impl
[2m[36m(func pid=81719)[0m     return forward_call(*args, **kwargs)
[2m[36m(func pid=81719)[0m   File "/mnt/iusers01/ct01/t18155cb/.local/lib/python3.9/site-packages/torch/nn/modules/container.py", line 217, in forward
[2m[36m(func pid=81719)[0m     input = module(input)
[2m[36m(func pid=81719)[0m   File "/mnt/iusers01/ct01/t18155cb/.local/lib/python3.9/site-packages/torch/nn/modules/module.py", line 1501, in _call_impl
[2m[36m(func pid=81719)[0m     return forward_call(*args, **kwargs)
[2m[36m(func pid=81719)[0m   File "/mnt/iusers01/ct01/t18155cb/.local/lib/python3.9/site-packages/torch/nn/modules/upsampling.py", line 156, in forward
[2m[36m(func pid=81719)[0m     return F.interpolate(input, self.size, self.scale_factor, self.mode, self.align_corners,
[2m[36m(func pid=81719)[0m   File "/mnt/iusers01/ct01/t18155cb/.local/lib/python3.9/site-packages/torch/nn/functional.py", line 3959, in interpolate
[2m[36m(func pid=81719)[0m     return torch._C._nn.upsample_bilinear2d(input, output_size, align_corners, scale_factors)
[2m[36m(func pid=81719)[0m RuntimeError: [enforce fail at alloc_cpu.cpp:75] err == 0. DefaultCPUAllocator: can't allocate memory: you tried to allocate 274877906944 bytes. Error code 12 (Cannot allocate memory)
2023-04-18 22:06:44,354	ERROR trial_runner.py:876 -- Trial train_model_99452_00002: Error processing event.
NoneType: None
2023-04-18 22:06:45,095	INFO trial_runner.py:803 -- starting train_model_99452_00008
[2m[36m(func pid=81625)[0m 2023-04-18 22:06:53,122	ERROR function_runner.py:281 -- Runner Thread raised error.
[2m[36m(func pid=81625)[0m Traceback (most recent call last):
[2m[36m(func pid=81625)[0m   File "/mnt/iusers01/ct01/t18155cb/.local/lib/python3.9/site-packages/ray/tune/function_runner.py", line 272, in run
[2m[36m(func pid=81625)[0m     self._entrypoint()
[2m[36m(func pid=81625)[0m   File "/mnt/iusers01/ct01/t18155cb/.local/lib/python3.9/site-packages/ray/tune/function_runner.py", line 348, in entrypoint
[2m[36m(func pid=81625)[0m     return self._trainable_func(
[2m[36m(func pid=81625)[0m   File "/mnt/iusers01/ct01/t18155cb/.local/lib/python3.9/site-packages/ray/util/tracing/tracing_helper.py", line 462, in _resume_span
[2m[36m(func pid=81625)[0m     return method(self, *_args, **_kwargs)
[2m[36m(func pid=81625)[0m   File "/mnt/iusers01/ct01/t18155cb/.local/lib/python3.9/site-packages/ray/tune/function_runner.py", line 640, in _trainable_func
[2m[36m(func pid=81625)[0m     output = fn()
[2m[36m(func pid=81625)[0m   File "/net/scratch2/t18155cb/SwinVisonTranslation_mIHC/Ray_tune_hyp.py", line 90, in train_model
[2m[36m(func pid=81625)[0m     outputs = model(inputs)
[2m[36m(func pid=81625)[0m   File "/mnt/iusers01/ct01/t18155cb/.local/lib/python3.9/site-packages/torch/nn/modules/module.py", line 1501, in _call_impl
[2m[36m(func pid=81625)[0m     return forward_call(*args, **kwargs)
[2m[36m(func pid=81625)[0m   File "/net/scratch2/t18155cb/SwinVisonTranslation_mIHC/SwinVisionTranformer.py", line 105, in forward
[2m[36m(func pid=81625)[0m     x = self.decoder(x)
[2m[36m(func pid=81625)[0m   File "/mnt/iusers01/ct01/t18155cb/.local/lib/python3.9/site-packages/torch/nn/modules/module.py", line 1501, in _call_impl
[2m[36m(func pid=81625)[0m     return forward_call(*args, **kwargs)
[2m[36m(func pid=81625)[0m   File "/mnt/iusers01/ct01/t18155cb/.local/lib/python3.9/site-packages/torch/nn/modules/container.py", line 217, in forward
[2m[36m(func pid=81625)[0m     input = module(input)
[2m[36m(func pid=81625)[0m   File "/mnt/iusers01/ct01/t18155cb/.local/lib/python3.9/site-packages/torch/nn/modules/module.py", line 1501, in _call_impl
[2m[36m(func pid=81625)[0m     return forward_call(*args, **kwargs)
[2m[36m(func pid=81625)[0m   File "/mnt/iusers01/ct01/t18155cb/.local/lib/python3.9/site-packages/torch/nn/modules/upsampling.py", line 156, in forward
[2m[36m(func pid=81625)[0m     return F.interpolate(input, self.size, self.scale_factor, self.mode, self.align_corners,
[2m[36m(func pid=81625)[0m   File "/mnt/iusers01/ct01/t18155cb/.local/lib/python3.9/site-packages/torch/nn/functional.py", line 3959, in interpolate
[2m[36m(func pid=81625)[0m     return torch._C._nn.upsample_bilinear2d(input, output_size, align_corners, scale_factors)
[2m[36m(func pid=81625)[0m RuntimeError: [enforce fail at alloc_cpu.cpp:75] err == 0. DefaultCPUAllocator: can't allocate memory: you tried to allocate 274877906944 bytes. Error code 12 (Cannot allocate memory)
[2m[36m(func pid=81625)[0m Exception in thread Thread-3:
[2m[36m(func pid=81625)[0m Traceback (most recent call last):
[2m[36m(func pid=81625)[0m   File "/opt/apps/apps/python/miniconda3/4.10.3/lib/python3.9/threading.py", line 954, in _bootstrap_inner
[2m[36m(func pid=81625)[0m     self.run()
[2m[36m(func pid=81625)[0m   File "/mnt/iusers01/ct01/t18155cb/.local/lib/python3.9/site-packages/ray/tune/function_runner.py", line 298, in run
[2m[36m(func pid=81625)[0m     raise e
[2m[36m(func pid=81625)[0m   File "/mnt/iusers01/ct01/t18155cb/.local/lib/python3.9/site-packages/ray/tune/function_runner.py", line 272, in run
[2m[36m(func pid=81625)[0m     self._entrypoint()
[2m[36m(func pid=81625)[0m   File "/mnt/iusers01/ct01/t18155cb/.local/lib/python3.9/site-packages/ray/tune/function_runner.py", line 348, in entrypoint
[2m[36m(func pid=81625)[0m     return self._trainable_func(
[2m[36m(func pid=81625)[0m   File "/mnt/iusers01/ct01/t18155cb/.local/lib/python3.9/site-packages/ray/util/tracing/tracing_helper.py", line 462, in _resume_span
[2m[36m(func pid=81625)[0m     return method(self, *_args, **_kwargs)
[2m[36m(func pid=81625)[0m   File "/mnt/iusers01/ct01/t18155cb/.local/lib/python3.9/site-packages/ray/tune/function_runner.py", line 640, in _trainable_func
[2m[36m(func pid=81625)[0m     output = fn()
[2m[36m(func pid=81625)[0m   File "/net/scratch2/t18155cb/SwinVisonTranslation_mIHC/Ray_tune_hyp.py", line 90, in train_model
[2m[36m(func pid=81625)[0m     outputs = model(inputs)
[2m[36m(func pid=81625)[0m   File "/mnt/iusers01/ct01/t18155cb/.local/lib/python3.9/site-packages/torch/nn/modules/module.py", line 1501, in _call_impl
[2m[36m(func pid=81625)[0m     return forward_call(*args, **kwargs)
[2m[36m(func pid=81625)[0m   File "/net/scratch2/t18155cb/SwinVisonTranslation_mIHC/SwinVisionTranformer.py", line 105, in forward
[2m[36m(func pid=81625)[0m     x = self.decoder(x)
[2m[36m(func pid=81625)[0m   File "/mnt/iusers01/ct01/t18155cb/.local/lib/python3.9/site-packages/torch/nn/modules/module.py", line 1501, in _call_impl
[2m[36m(func pid=81625)[0m     return forward_call(*args, **kwargs)
[2m[36m(func pid=81625)[0m   File "/mnt/iusers01/ct01/t18155cb/.local/lib/python3.9/site-packages/torch/nn/modules/container.py", line 217, in forward
[2m[36m(func pid=81625)[0m     input = module(input)
[2m[36m(func pid=81625)[0m   File "/mnt/iusers01/ct01/t18155cb/.local/lib/python3.9/site-packages/torch/nn/modules/module.py", line 1501, in _call_impl
[2m[36m(func pid=81625)[0m     return forward_call(*args, **kwargs)
[2m[36m(func pid=81625)[0m   File "/mnt/iusers01/ct01/t18155cb/.local/lib/python3.9/site-packages/torch/nn/modules/upsampling.py", line 156, in forward
[2m[36m(func pid=81625)[0m     return F.interpolate(input, self.size, self.scale_factor, self.mode, self.align_corners,
[2m[36m(func pid=81625)[0m   File "/mnt/iusers01/ct01/t18155cb/.local/lib/python3.9/site-packages/torch/nn/functional.py", line 3959, in interpolate
[2m[36m(func pid=81625)[0m     return torch._C._nn.upsample_bilinear2d(input, output_size, align_corners, scale_factors)
[2m[36m(func pid=81625)[0m RuntimeError: [enforce fail at alloc_cpu.cpp:75] err == 0. DefaultCPUAllocator: can't allocate memory: you tried to allocate 274877906944 bytes. Error code 12 (Cannot allocate memory)
2023-04-18 22:06:56,992	ERROR trial_runner.py:876 -- Trial train_model_99452_00001: Error processing event.
NoneType: None
[2m[36m(func pid=94504)[0m /mnt/iusers01/ct01/t18155cb/.local/lib/python3.9/site-packages/torch/functional.py:504: UserWarning: torch.meshgrid: in an upcoming release, it will be required to pass the indexing argument. (Triggered internally at ../aten/src/ATen/native/TensorShape.cpp:3483.)
[2m[36m(func pid=94504)[0m   return _VF.meshgrid(tensors, **kwargs)  # type: ignore[attr-defined]
2023-04-18 22:06:57,096	INFO trial_runner.py:803 -- starting train_model_99452_00009
[2m[36m(func pid=94504)[0m /mnt/iusers01/ct01/t18155cb/.local/lib/python3.9/site-packages/torch/cuda/amp/grad_scaler.py:120: UserWarning: torch.cuda.amp.GradScaler is enabled, but CUDA is not available.  Disabling.
[2m[36m(func pid=94504)[0m   warnings.warn("torch.cuda.amp.GradScaler is enabled, but CUDA is not available.  Disabling.")
[2m[36m(func pid=94504)[0m /mnt/iusers01/ct01/t18155cb/.local/lib/python3.9/site-packages/torch/amp/autocast_mode.py:204: UserWarning: User provided device_type of 'cuda', but CUDA is not available. Disabling
[2m[36m(func pid=94504)[0m   warnings.warn('User provided device_type of \'cuda\', but CUDA is not available. Disabling')
[2m[36m(func pid=94606)[0m /mnt/iusers01/ct01/t18155cb/.local/lib/python3.9/site-packages/torch/functional.py:504: UserWarning: torch.meshgrid: in an upcoming release, it will be required to pass the indexing argument. (Triggered internally at ../aten/src/ATen/native/TensorShape.cpp:3483.)
[2m[36m(func pid=94606)[0m   return _VF.meshgrid(tensors, **kwargs)  # type: ignore[attr-defined]
[2m[36m(func pid=94606)[0m /mnt/iusers01/ct01/t18155cb/.local/lib/python3.9/site-packages/torch/cuda/amp/grad_scaler.py:120: UserWarning: torch.cuda.amp.GradScaler is enabled, but CUDA is not available.  Disabling.
[2m[36m(func pid=94606)[0m   warnings.warn("torch.cuda.amp.GradScaler is enabled, but CUDA is not available.  Disabling.")
[2m[36m(func pid=94606)[0m /mnt/iusers01/ct01/t18155cb/.local/lib/python3.9/site-packages/torch/amp/autocast_mode.py:204: UserWarning: User provided device_type of 'cuda', but CUDA is not available. Disabling
[2m[36m(func pid=94606)[0m   warnings.warn('User provided device_type of \'cuda\', but CUDA is not available. Disabling')
[2m[36m(func pid=88838)[0m 2023-04-18 22:16:30,130	ERROR function_runner.py:281 -- Runner Thread raised error.
[2m[36m(func pid=88838)[0m Traceback (most recent call last):
[2m[36m(func pid=88838)[0m   File "/mnt/iusers01/ct01/t18155cb/.local/lib/python3.9/site-packages/ray/tune/function_runner.py", line 272, in run
[2m[36m(func pid=88838)[0m     self._entrypoint()
[2m[36m(func pid=88838)[0m   File "/mnt/iusers01/ct01/t18155cb/.local/lib/python3.9/site-packages/ray/tune/function_runner.py", line 348, in entrypoint
[2m[36m(func pid=88838)[0m     return self._trainable_func(
[2m[36m(func pid=88838)[0m   File "/mnt/iusers01/ct01/t18155cb/.local/lib/python3.9/site-packages/ray/util/tracing/tracing_helper.py", line 462, in _resume_span
[2m[36m(func pid=88838)[0m     return method(self, *_args, **_kwargs)
[2m[36m(func pid=88838)[0m   File "/mnt/iusers01/ct01/t18155cb/.local/lib/python3.9/site-packages/ray/tune/function_runner.py", line 640, in _trainable_func
[2m[36m(func pid=88838)[0m     output = fn()
[2m[36m(func pid=88838)[0m   File "/net/scratch2/t18155cb/SwinVisonTranslation_mIHC/Ray_tune_hyp.py", line 90, in train_model
[2m[36m(func pid=88838)[0m     outputs = model(inputs)
[2m[36m(func pid=88838)[0m   File "/mnt/iusers01/ct01/t18155cb/.local/lib/python3.9/site-packages/torch/nn/modules/module.py", line 1501, in _call_impl
[2m[36m(func pid=88838)[0m     return forward_call(*args, **kwargs)
[2m[36m(func pid=88838)[0m   File "/net/scratch2/t18155cb/SwinVisonTranslation_mIHC/SwinVisionTranformer.py", line 106, in forward
[2m[36m(func pid=88838)[0m     x = x + x_skip
[2m[36m(func pid=88838)[0m RuntimeError: The size of tensor a (65536) must match the size of tensor b (64) at non-singleton dimension 3
[2m[36m(func pid=88838)[0m Exception in thread Thread-3:
[2m[36m(func pid=88838)[0m Traceback (most recent call last):
[2m[36m(func pid=88838)[0m   File "/opt/apps/apps/python/miniconda3/4.10.3/lib/python3.9/threading.py", line 954, in _bootstrap_inner
[2m[36m(func pid=88838)[0m     self.run()
[2m[36m(func pid=88838)[0m   File "/mnt/iusers01/ct01/t18155cb/.local/lib/python3.9/site-packages/ray/tune/function_runner.py", line 298, in run
[2m[36m(func pid=88838)[0m     raise e
[2m[36m(func pid=88838)[0m   File "/mnt/iusers01/ct01/t18155cb/.local/lib/python3.9/site-packages/ray/tune/function_runner.py", line 272, in run
[2m[36m(func pid=88838)[0m     self._entrypoint()
[2m[36m(func pid=88838)[0m   File "/mnt/iusers01/ct01/t18155cb/.local/lib/python3.9/site-packages/ray/tune/function_runner.py", line 348, in entrypoint
[2m[36m(func pid=88838)[0m     return self._trainable_func(
[2m[36m(func pid=88838)[0m   File "/mnt/iusers01/ct01/t18155cb/.local/lib/python3.9/site-packages/ray/util/tracing/tracing_helper.py", line 462, in _resume_span
[2m[36m(func pid=88838)[0m     return method(self, *_args, **_kwargs)
[2m[36m(func pid=88838)[0m   File "/mnt/iusers01/ct01/t18155cb/.local/lib/python3.9/site-packages/ray/tune/function_runner.py", line 640, in _trainable_func
[2m[36m(func pid=88838)[0m     output = fn()
[2m[36m(func pid=88838)[0m   File "/net/scratch2/t18155cb/SwinVisonTranslation_mIHC/Ray_tune_hyp.py", line 90, in train_model
[2m[36m(func pid=88838)[0m     outputs = model(inputs)
[2m[36m(func pid=88838)[0m   File "/mnt/iusers01/ct01/t18155cb/.local/lib/python3.9/site-packages/torch/nn/modules/module.py", line 1501, in _call_impl
[2m[36m(func pid=88838)[0m     return forward_call(*args, **kwargs)
[2m[36m(func pid=88838)[0m   File "/net/scratch2/t18155cb/SwinVisonTranslation_mIHC/SwinVisionTranformer.py", line 106, in forward
[2m[36m(func pid=88838)[0m     x = x + x_skip
[2m[36m(func pid=88838)[0m RuntimeError: The size of tensor a (65536) must match the size of tensor b (64) at non-singleton dimension 3
2023-04-18 22:16:38,774	ERROR trial_runner.py:876 -- Trial train_model_99452_00005: Error processing event.
NoneType: None
2023-04-18 22:16:39,146	INFO trial_runner.py:803 -- starting train_model_99452_00010
[2m[36m(func pid=95841)[0m /mnt/iusers01/ct01/t18155cb/.local/lib/python3.9/site-packages/torch/functional.py:504: UserWarning: torch.meshgrid: in an upcoming release, it will be required to pass the indexing argument. (Triggered internally at ../aten/src/ATen/native/TensorShape.cpp:3483.)
[2m[36m(func pid=95841)[0m   return _VF.meshgrid(tensors, **kwargs)  # type: ignore[attr-defined]
[2m[36m(func pid=95841)[0m /mnt/iusers01/ct01/t18155cb/.local/lib/python3.9/site-packages/torch/cuda/amp/grad_scaler.py:120: UserWarning: torch.cuda.amp.GradScaler is enabled, but CUDA is not available.  Disabling.
[2m[36m(func pid=95841)[0m   warnings.warn("torch.cuda.amp.GradScaler is enabled, but CUDA is not available.  Disabling.")
[2m[36m(func pid=95841)[0m /mnt/iusers01/ct01/t18155cb/.local/lib/python3.9/site-packages/torch/amp/autocast_mode.py:204: UserWarning: User provided device_type of 'cuda', but CUDA is not available. Disabling
[2m[36m(func pid=95841)[0m   warnings.warn('User provided device_type of \'cuda\', but CUDA is not available. Disabling')
[2m[36m(func pid=92729)[0m 2023-04-18 22:20:37,317	ERROR function_runner.py:281 -- Runner Thread raised error.
[2m[36m(func pid=92729)[0m Traceback (most recent call last):
[2m[36m(func pid=92729)[0m   File "/mnt/iusers01/ct01/t18155cb/.local/lib/python3.9/site-packages/ray/tune/function_runner.py", line 272, in run
[2m[36m(func pid=92729)[0m     self._entrypoint()
[2m[36m(func pid=92729)[0m   File "/mnt/iusers01/ct01/t18155cb/.local/lib/python3.9/site-packages/ray/tune/function_runner.py", line 348, in entrypoint
[2m[36m(func pid=92729)[0m     return self._trainable_func(
[2m[36m(func pid=92729)[0m   File "/mnt/iusers01/ct01/t18155cb/.local/lib/python3.9/site-packages/ray/util/tracing/tracing_helper.py", line 462, in _resume_span
[2m[36m(func pid=92729)[0m     return method(self, *_args, **_kwargs)
[2m[36m(func pid=92729)[0m   File "/mnt/iusers01/ct01/t18155cb/.local/lib/python3.9/site-packages/ray/tune/function_runner.py", line 640, in _trainable_func
[2m[36m(func pid=92729)[0m     output = fn()
[2m[36m(func pid=92729)[0m   File "/net/scratch2/t18155cb/SwinVisonTranslation_mIHC/Ray_tune_hyp.py", line 90, in train_model
[2m[36m(func pid=92729)[0m     outputs = model(inputs)
[2m[36m(func pid=92729)[0m   File "/mnt/iusers01/ct01/t18155cb/.local/lib/python3.9/site-packages/torch/nn/modules/module.py", line 1501, in _call_impl
[2m[36m(func pid=92729)[0m     return forward_call(*args, **kwargs)
[2m[36m(func pid=92729)[0m   File "/net/scratch2/t18155cb/SwinVisonTranslation_mIHC/SwinVisionTranformer.py", line 106, in forward
[2m[36m(func pid=92729)[0m     x = x + x_skip
[2m[36m(func pid=92729)[0m RuntimeError: The size of tensor a (65536) must match the size of tensor b (64) at non-singleton dimension 3
[2m[36m(func pid=92729)[0m Exception in thread Thread-3:
[2m[36m(func pid=92729)[0m Traceback (most recent call last):
[2m[36m(func pid=92729)[0m   File "/opt/apps/apps/python/miniconda3/4.10.3/lib/python3.9/threading.py", line 954, in _bootstrap_inner
[2m[36m(func pid=92729)[0m     self.run()
[2m[36m(func pid=92729)[0m   File "/mnt/iusers01/ct01/t18155cb/.local/lib/python3.9/site-packages/ray/tune/function_runner.py", line 298, in run
[2m[36m(func pid=92729)[0m     raise e
[2m[36m(func pid=92729)[0m   File "/mnt/iusers01/ct01/t18155cb/.local/lib/python3.9/site-packages/ray/tune/function_runner.py", line 272, in run
[2m[36m(func pid=92729)[0m     self._entrypoint()
[2m[36m(func pid=92729)[0m   File "/mnt/iusers01/ct01/t18155cb/.local/lib/python3.9/site-packages/ray/tune/function_runner.py", line 348, in entrypoint
[2m[36m(func pid=92729)[0m     return self._trainable_func(
[2m[36m(func pid=92729)[0m   File "/mnt/iusers01/ct01/t18155cb/.local/lib/python3.9/site-packages/ray/util/tracing/tracing_helper.py", line 462, in _resume_span
[2m[36m(func pid=92729)[0m     return method(self, *_args, **_kwargs)
[2m[36m(func pid=92729)[0m   File "/mnt/iusers01/ct01/t18155cb/.local/lib/python3.9/site-packages/ray/tune/function_runner.py", line 640, in _trainable_func
[2m[36m(func pid=92729)[0m     output = fn()
[2m[36m(func pid=92729)[0m   File "/net/scratch2/t18155cb/SwinVisonTranslation_mIHC/Ray_tune_hyp.py", line 90, in train_model
[2m[36m(func pid=92729)[0m     outputs = model(inputs)
[2m[36m(func pid=92729)[0m   File "/mnt/iusers01/ct01/t18155cb/.local/lib/python3.9/site-packages/torch/nn/modules/module.py", line 1501, in _call_impl
[2m[36m(func pid=92729)[0m     return forward_call(*args, **kwargs)
[2m[36m(func pid=92729)[0m   File "/net/scratch2/t18155cb/SwinVisonTranslation_mIHC/SwinVisionTranformer.py", line 106, in forward
[2m[36m(func pid=92729)[0m     x = x + x_skip
[2m[36m(func pid=92729)[0m RuntimeError: The size of tensor a (65536) must match the size of tensor b (64) at non-singleton dimension 3
2023-04-18 22:20:40,515	ERROR trial_runner.py:876 -- Trial train_model_99452_00007: Error processing event.
NoneType: None
2023-04-18 22:20:41,164	INFO trial_runner.py:803 -- starting train_model_99452_00011
[2m[36m(func pid=96433)[0m /mnt/iusers01/ct01/t18155cb/.local/lib/python3.9/site-packages/torch/functional.py:504: UserWarning: torch.meshgrid: in an upcoming release, it will be required to pass the indexing argument. (Triggered internally at ../aten/src/ATen/native/TensorShape.cpp:3483.)
[2m[36m(func pid=96433)[0m   return _VF.meshgrid(tensors, **kwargs)  # type: ignore[attr-defined]
[2m[36m(func pid=96433)[0m /mnt/iusers01/ct01/t18155cb/.local/lib/python3.9/site-packages/torch/cuda/amp/grad_scaler.py:120: UserWarning: torch.cuda.amp.GradScaler is enabled, but CUDA is not available.  Disabling.
[2m[36m(func pid=96433)[0m   warnings.warn("torch.cuda.amp.GradScaler is enabled, but CUDA is not available.  Disabling.")
[2m[36m(func pid=96433)[0m /mnt/iusers01/ct01/t18155cb/.local/lib/python3.9/site-packages/torch/amp/autocast_mode.py:204: UserWarning: User provided device_type of 'cuda', but CUDA is not available. Disabling
[2m[36m(func pid=96433)[0m   warnings.warn('User provided device_type of \'cuda\', but CUDA is not available. Disabling')
[2m[36m(func pid=94606)[0m 2023-04-18 22:34:46,891	ERROR function_runner.py:281 -- Runner Thread raised error.
[2m[36m(func pid=94606)[0m Traceback (most recent call last):
[2m[36m(func pid=94606)[0m   File "/mnt/iusers01/ct01/t18155cb/.local/lib/python3.9/site-packages/ray/tune/function_runner.py", line 272, in run
[2m[36m(func pid=94606)[0m     self._entrypoint()
[2m[36m(func pid=94606)[0m   File "/mnt/iusers01/ct01/t18155cb/.local/lib/python3.9/site-packages/ray/tune/function_runner.py", line 348, in entrypoint
[2m[36m(func pid=94606)[0m     return self._trainable_func(
[2m[36m(func pid=94606)[0m   File "/mnt/iusers01/ct01/t18155cb/.local/lib/python3.9/site-packages/ray/util/tracing/tracing_helper.py", line 462, in _resume_span
[2m[36m(func pid=94606)[0m     return method(self, *_args, **_kwargs)
[2m[36m(func pid=94606)[0m   File "/mnt/iusers01/ct01/t18155cb/.local/lib/python3.9/site-packages/ray/tune/function_runner.py", line 640, in _trainable_func
[2m[36m(func pid=94606)[0m     output = fn()
[2m[36m(func pid=94606)[0m   File "/net/scratch2/t18155cb/SwinVisonTranslation_mIHC/Ray_tune_hyp.py", line 90, in train_model
[2m[36m(func pid=94606)[0m     outputs = model(inputs)
[2m[36m(func pid=94606)[0m   File "/mnt/iusers01/ct01/t18155cb/.local/lib/python3.9/site-packages/torch/nn/modules/module.py", line 1501, in _call_impl
[2m[36m(func pid=94606)[0m     return forward_call(*args, **kwargs)
[2m[36m(func pid=94606)[0m   File "/net/scratch2/t18155cb/SwinVisonTranslation_mIHC/SwinVisionTranformer.py", line 106, in forward
[2m[36m(func pid=94606)[0m     x = x + x_skip
[2m[36m(func pid=94606)[0m RuntimeError: The size of tensor a (65536) must match the size of tensor b (64) at non-singleton dimension 3
[2m[36m(func pid=94606)[0m Exception in thread Thread-3:
[2m[36m(func pid=94606)[0m Traceback (most recent call last):
[2m[36m(func pid=94606)[0m   File "/opt/apps/apps/python/miniconda3/4.10.3/lib/python3.9/threading.py", line 954, in _bootstrap_inner
[2m[36m(func pid=94606)[0m     self.run()
[2m[36m(func pid=94606)[0m   File "/mnt/iusers01/ct01/t18155cb/.local/lib/python3.9/site-packages/ray/tune/function_runner.py", line 298, in run
[2m[36m(func pid=94606)[0m     raise e
[2m[36m(func pid=94606)[0m   File "/mnt/iusers01/ct01/t18155cb/.local/lib/python3.9/site-packages/ray/tune/function_runner.py", line 272, in run
[2m[36m(func pid=94606)[0m     self._entrypoint()
[2m[36m(func pid=94606)[0m   File "/mnt/iusers01/ct01/t18155cb/.local/lib/python3.9/site-packages/ray/tune/function_runner.py", line 348, in entrypoint
[2m[36m(func pid=94606)[0m     return self._trainable_func(
[2m[36m(func pid=94606)[0m   File "/mnt/iusers01/ct01/t18155cb/.local/lib/python3.9/site-packages/ray/util/tracing/tracing_helper.py", line 462, in _resume_span
[2m[36m(func pid=94606)[0m     return method(self, *_args, **_kwargs)
[2m[36m(func pid=94606)[0m   File "/mnt/iusers01/ct01/t18155cb/.local/lib/python3.9/site-packages/ray/tune/function_runner.py", line 640, in _trainable_func
[2m[36m(func pid=94606)[0m     output = fn()
[2m[36m(func pid=94606)[0m   File "/net/scratch2/t18155cb/SwinVisonTranslation_mIHC/Ray_tune_hyp.py", line 90, in train_model
[2m[36m(func pid=94606)[0m     outputs = model(inputs)
[2m[36m(func pid=94606)[0m   File "/mnt/iusers01/ct01/t18155cb/.local/lib/python3.9/site-packages/torch/nn/modules/module.py", line 1501, in _call_impl
[2m[36m(func pid=94606)[0m     return forward_call(*args, **kwargs)
[2m[36m(func pid=94606)[0m   File "/net/scratch2/t18155cb/SwinVisonTranslation_mIHC/SwinVisionTranformer.py", line 106, in forward
[2m[36m(func pid=94606)[0m     x = x + x_skip
[2m[36m(func pid=94606)[0m RuntimeError: The size of tensor a (65536) must match the size of tensor b (64) at non-singleton dimension 3
2023-04-18 22:34:51,235	ERROR trial_runner.py:876 -- Trial train_model_99452_00009: Error processing event.
NoneType: None
2023-04-18 22:34:52,232	INFO trial_runner.py:803 -- starting train_model_99452_00012
[2m[36m(func pid=98397)[0m /mnt/iusers01/ct01/t18155cb/.local/lib/python3.9/site-packages/torch/functional.py:504: UserWarning: torch.meshgrid: in an upcoming release, it will be required to pass the indexing argument. (Triggered internally at ../aten/src/ATen/native/TensorShape.cpp:3483.)
[2m[36m(func pid=98397)[0m   return _VF.meshgrid(tensors, **kwargs)  # type: ignore[attr-defined]
[2m[36m(func pid=98397)[0m /mnt/iusers01/ct01/t18155cb/.local/lib/python3.9/site-packages/torch/cuda/amp/grad_scaler.py:120: UserWarning: torch.cuda.amp.GradScaler is enabled, but CUDA is not available.  Disabling.
[2m[36m(func pid=98397)[0m   warnings.warn("torch.cuda.amp.GradScaler is enabled, but CUDA is not available.  Disabling.")
[2m[36m(func pid=98397)[0m /mnt/iusers01/ct01/t18155cb/.local/lib/python3.9/site-packages/torch/amp/autocast_mode.py:204: UserWarning: User provided device_type of 'cuda', but CUDA is not available. Disabling
[2m[36m(func pid=98397)[0m   warnings.warn('User provided device_type of \'cuda\', but CUDA is not available. Disabling')
[2m[36m(func pid=98397)[0m 2023-04-18 23:05:44,340	ERROR function_runner.py:281 -- Runner Thread raised error.
[2m[36m(func pid=98397)[0m Traceback (most recent call last):
[2m[36m(func pid=98397)[0m   File "/mnt/iusers01/ct01/t18155cb/.local/lib/python3.9/site-packages/ray/tune/function_runner.py", line 272, in run
[2m[36m(func pid=98397)[0m     self._entrypoint()
[2m[36m(func pid=98397)[0m   File "/mnt/iusers01/ct01/t18155cb/.local/lib/python3.9/site-packages/ray/tune/function_runner.py", line 348, in entrypoint
[2m[36m(func pid=98397)[0m     return self._trainable_func(
[2m[36m(func pid=98397)[0m   File "/mnt/iusers01/ct01/t18155cb/.local/lib/python3.9/site-packages/ray/util/tracing/tracing_helper.py", line 462, in _resume_span
[2m[36m(func pid=98397)[0m     return method(self, *_args, **_kwargs)
[2m[36m(func pid=98397)[0m   File "/mnt/iusers01/ct01/t18155cb/.local/lib/python3.9/site-packages/ray/tune/function_runner.py", line 640, in _trainable_func
[2m[36m(func pid=98397)[0m     output = fn()
[2m[36m(func pid=98397)[0m   File "/net/scratch2/t18155cb/SwinVisonTranslation_mIHC/Ray_tune_hyp.py", line 90, in train_model
[2m[36m(func pid=98397)[0m     outputs = model(inputs)
[2m[36m(func pid=98397)[0m   File "/mnt/iusers01/ct01/t18155cb/.local/lib/python3.9/site-packages/torch/nn/modules/module.py", line 1501, in _call_impl
[2m[36m(func pid=98397)[0m     return forward_call(*args, **kwargs)
[2m[36m(func pid=98397)[0m   File "/net/scratch2/t18155cb/SwinVisonTranslation_mIHC/SwinVisionTranformer.py", line 106, in forward
[2m[36m(func pid=98397)[0m     x = x + x_skip
[2m[36m(func pid=98397)[0m RuntimeError: The size of tensor a (65536) must match the size of tensor b (64) at non-singleton dimension 3
[2m[36m(func pid=98397)[0m Exception in thread Thread-3:
[2m[36m(func pid=98397)[0m Traceback (most recent call last):
[2m[36m(func pid=98397)[0m   File "/opt/apps/apps/python/miniconda3/4.10.3/lib/python3.9/threading.py", line 954, in _bootstrap_inner
[2m[36m(func pid=98397)[0m     self.run()
[2m[36m(func pid=98397)[0m   File "/mnt/iusers01/ct01/t18155cb/.local/lib/python3.9/site-packages/ray/tune/function_runner.py", line 298, in run
[2m[36m(func pid=98397)[0m     raise e
[2m[36m(func pid=98397)[0m   File "/mnt/iusers01/ct01/t18155cb/.local/lib/python3.9/site-packages/ray/tune/function_runner.py", line 272, in run
[2m[36m(func pid=98397)[0m     self._entrypoint()
[2m[36m(func pid=98397)[0m   File "/mnt/iusers01/ct01/t18155cb/.local/lib/python3.9/site-packages/ray/tune/function_runner.py", line 348, in entrypoint
[2m[36m(func pid=98397)[0m     return self._trainable_func(
[2m[36m(func pid=98397)[0m   File "/mnt/iusers01/ct01/t18155cb/.local/lib/python3.9/site-packages/ray/util/tracing/tracing_helper.py", line 462, in _resume_span
[2m[36m(func pid=98397)[0m     return method(self, *_args, **_kwargs)
[2m[36m(func pid=98397)[0m   File "/mnt/iusers01/ct01/t18155cb/.local/lib/python3.9/site-packages/ray/tune/function_runner.py", line 640, in _trainable_func
[2m[36m(func pid=98397)[0m     output = fn()
[2m[36m(func pid=98397)[0m   File "/net/scratch2/t18155cb/SwinVisonTranslation_mIHC/Ray_tune_hyp.py", line 90, in train_model
[2m[36m(func pid=98397)[0m     outputs = model(inputs)
[2m[36m(func pid=98397)[0m   File "/mnt/iusers01/ct01/t18155cb/.local/lib/python3.9/site-packages/torch/nn/modules/module.py", line 1501, in _call_impl
[2m[36m(func pid=98397)[0m     return forward_call(*args, **kwargs)
[2m[36m(func pid=98397)[0m   File "/net/scratch2/t18155cb/SwinVisonTranslation_mIHC/SwinVisionTranformer.py", line 106, in forward
[2m[36m(func pid=98397)[0m     x = x + x_skip
[2m[36m(func pid=98397)[0m RuntimeError: The size of tensor a (65536) must match the size of tensor b (64) at non-singleton dimension 3
2023-04-18 23:05:48,830	ERROR trial_runner.py:876 -- Trial train_model_99452_00012: Error processing event.
NoneType: None
2023-04-18 23:05:49,402	INFO trial_runner.py:803 -- starting train_model_99452_00013
[2m[36m(func pid=102165)[0m /mnt/iusers01/ct01/t18155cb/.local/lib/python3.9/site-packages/torch/functional.py:504: UserWarning: torch.meshgrid: in an upcoming release, it will be required to pass the indexing argument. (Triggered internally at ../aten/src/ATen/native/TensorShape.cpp:3483.)
[2m[36m(func pid=102165)[0m   return _VF.meshgrid(tensors, **kwargs)  # type: ignore[attr-defined]
[2m[36m(func pid=102165)[0m /mnt/iusers01/ct01/t18155cb/.local/lib/python3.9/site-packages/torch/cuda/amp/grad_scaler.py:120: UserWarning: torch.cuda.amp.GradScaler is enabled, but CUDA is not available.  Disabling.
[2m[36m(func pid=102165)[0m   warnings.warn("torch.cuda.amp.GradScaler is enabled, but CUDA is not available.  Disabling.")
[2m[36m(func pid=102165)[0m /mnt/iusers01/ct01/t18155cb/.local/lib/python3.9/site-packages/torch/amp/autocast_mode.py:204: UserWarning: User provided device_type of 'cuda', but CUDA is not available. Disabling
[2m[36m(func pid=102165)[0m   warnings.warn('User provided device_type of \'cuda\', but CUDA is not available. Disabling')
[2m[36m(func pid=95841)[0m 2023-04-18 23:10:26,571	ERROR function_runner.py:281 -- Runner Thread raised error.
[2m[36m(func pid=95841)[0m Traceback (most recent call last):
[2m[36m(func pid=95841)[0m   File "/mnt/iusers01/ct01/t18155cb/.local/lib/python3.9/site-packages/ray/tune/function_runner.py", line 272, in run
[2m[36m(func pid=95841)[0m     self._entrypoint()
[2m[36m(func pid=95841)[0m   File "/mnt/iusers01/ct01/t18155cb/.local/lib/python3.9/site-packages/ray/tune/function_runner.py", line 348, in entrypoint
[2m[36m(func pid=95841)[0m     return self._trainable_func(
[2m[36m(func pid=95841)[0m   File "/mnt/iusers01/ct01/t18155cb/.local/lib/python3.9/site-packages/ray/util/tracing/tracing_helper.py", line 462, in _resume_span
[2m[36m(func pid=95841)[0m     return method(self, *_args, **_kwargs)
[2m[36m(func pid=95841)[0m   File "/mnt/iusers01/ct01/t18155cb/.local/lib/python3.9/site-packages/ray/tune/function_runner.py", line 640, in _trainable_func
[2m[36m(func pid=95841)[0m     output = fn()
[2m[36m(func pid=95841)[0m   File "/net/scratch2/t18155cb/SwinVisonTranslation_mIHC/Ray_tune_hyp.py", line 90, in train_model
[2m[36m(func pid=95841)[0m     outputs = model(inputs)
[2m[36m(func pid=95841)[0m   File "/mnt/iusers01/ct01/t18155cb/.local/lib/python3.9/site-packages/torch/nn/modules/module.py", line 1501, in _call_impl
[2m[36m(func pid=95841)[0m     return forward_call(*args, **kwargs)
[2m[36m(func pid=95841)[0m   File "/net/scratch2/t18155cb/SwinVisonTranslation_mIHC/SwinVisionTranformer.py", line 106, in forward
[2m[36m(func pid=95841)[0m     x = x + x_skip
[2m[36m(func pid=95841)[0m RuntimeError: The size of tensor a (65536) must match the size of tensor b (64) at non-singleton dimension 3
[2m[36m(func pid=95841)[0m Exception in thread Thread-3:
[2m[36m(func pid=95841)[0m Traceback (most recent call last):
[2m[36m(func pid=95841)[0m   File "/opt/apps/apps/python/miniconda3/4.10.3/lib/python3.9/threading.py", line 954, in _bootstrap_inner
[2m[36m(func pid=95841)[0m     self.run()
[2m[36m(func pid=95841)[0m   File "/mnt/iusers01/ct01/t18155cb/.local/lib/python3.9/site-packages/ray/tune/function_runner.py", line 298, in run
[2m[36m(func pid=95841)[0m     raise e
[2m[36m(func pid=95841)[0m   File "/mnt/iusers01/ct01/t18155cb/.local/lib/python3.9/site-packages/ray/tune/function_runner.py", line 272, in run
[2m[36m(func pid=95841)[0m     self._entrypoint()
[2m[36m(func pid=95841)[0m   File "/mnt/iusers01/ct01/t18155cb/.local/lib/python3.9/site-packages/ray/tune/function_runner.py", line 348, in entrypoint
[2m[36m(func pid=95841)[0m     return self._trainable_func(
[2m[36m(func pid=95841)[0m   File "/mnt/iusers01/ct01/t18155cb/.local/lib/python3.9/site-packages/ray/util/tracing/tracing_helper.py", line 462, in _resume_span
[2m[36m(func pid=95841)[0m     return method(self, *_args, **_kwargs)
[2m[36m(func pid=95841)[0m   File "/mnt/iusers01/ct01/t18155cb/.local/lib/python3.9/site-packages/ray/tune/function_runner.py", line 640, in _trainable_func
[2m[36m(func pid=95841)[0m     output = fn()
[2m[36m(func pid=95841)[0m   File "/net/scratch2/t18155cb/SwinVisonTranslation_mIHC/Ray_tune_hyp.py", line 90, in train_model
[2m[36m(func pid=95841)[0m     outputs = model(inputs)
[2m[36m(func pid=95841)[0m   File "/mnt/iusers01/ct01/t18155cb/.local/lib/python3.9/site-packages/torch/nn/modules/module.py", line 1501, in _call_impl
[2m[36m(func pid=95841)[0m     return forward_call(*args, **kwargs)
[2m[36m(func pid=95841)[0m   File "/net/scratch2/t18155cb/SwinVisonTranslation_mIHC/SwinVisionTranformer.py", line 106, in forward
[2m[36m(func pid=95841)[0m     x = x + x_skip
[2m[36m(func pid=95841)[0m RuntimeError: The size of tensor a (65536) must match the size of tensor b (64) at non-singleton dimension 3
2023-04-18 23:10:36,405	ERROR trial_runner.py:876 -- Trial train_model_99452_00010: Error processing event.
NoneType: None
2023-04-18 23:10:37,419	INFO trial_runner.py:803 -- starting train_model_99452_00014
[2m[36m(func pid=102847)[0m /mnt/iusers01/ct01/t18155cb/.local/lib/python3.9/site-packages/torch/functional.py:504: UserWarning: torch.meshgrid: in an upcoming release, it will be required to pass the indexing argument. (Triggered internally at ../aten/src/ATen/native/TensorShape.cpp:3483.)
[2m[36m(func pid=102847)[0m   return _VF.meshgrid(tensors, **kwargs)  # type: ignore[attr-defined]
[2m[36m(func pid=102847)[0m /mnt/iusers01/ct01/t18155cb/.local/lib/python3.9/site-packages/torch/cuda/amp/grad_scaler.py:120: UserWarning: torch.cuda.amp.GradScaler is enabled, but CUDA is not available.  Disabling.
[2m[36m(func pid=102847)[0m   warnings.warn("torch.cuda.amp.GradScaler is enabled, but CUDA is not available.  Disabling.")
[2m[36m(func pid=102847)[0m /mnt/iusers01/ct01/t18155cb/.local/lib/python3.9/site-packages/torch/amp/autocast_mode.py:204: UserWarning: User provided device_type of 'cuda', but CUDA is not available. Disabling
[2m[36m(func pid=102847)[0m   warnings.warn('User provided device_type of \'cuda\', but CUDA is not available. Disabling')
[2m[36m(func pid=96433)[0m 2023-04-18 23:14:38,079	ERROR function_runner.py:281 -- Runner Thread raised error.
[2m[36m(func pid=96433)[0m Traceback (most recent call last):
[2m[36m(func pid=96433)[0m   File "/mnt/iusers01/ct01/t18155cb/.local/lib/python3.9/site-packages/ray/tune/function_runner.py", line 272, in run
[2m[36m(func pid=96433)[0m     self._entrypoint()
[2m[36m(func pid=96433)[0m   File "/mnt/iusers01/ct01/t18155cb/.local/lib/python3.9/site-packages/ray/tune/function_runner.py", line 348, in entrypoint
[2m[36m(func pid=96433)[0m     return self._trainable_func(
[2m[36m(func pid=96433)[0m   File "/mnt/iusers01/ct01/t18155cb/.local/lib/python3.9/site-packages/ray/util/tracing/tracing_helper.py", line 462, in _resume_span
[2m[36m(func pid=96433)[0m     return method(self, *_args, **_kwargs)
[2m[36m(func pid=96433)[0m   File "/mnt/iusers01/ct01/t18155cb/.local/lib/python3.9/site-packages/ray/tune/function_runner.py", line 640, in _trainable_func
[2m[36m(func pid=96433)[0m     output = fn()
[2m[36m(func pid=96433)[0m   File "/net/scratch2/t18155cb/SwinVisonTranslation_mIHC/Ray_tune_hyp.py", line 90, in train_model
[2m[36m(func pid=96433)[0m     outputs = model(inputs)
[2m[36m(func pid=96433)[0m   File "/mnt/iusers01/ct01/t18155cb/.local/lib/python3.9/site-packages/torch/nn/modules/module.py", line 1501, in _call_impl
[2m[36m(func pid=96433)[0m     return forward_call(*args, **kwargs)
[2m[36m(func pid=96433)[0m   File "/net/scratch2/t18155cb/SwinVisonTranslation_mIHC/SwinVisionTranformer.py", line 106, in forward
[2m[36m(func pid=96433)[0m     x = x + x_skip
[2m[36m(func pid=96433)[0m RuntimeError: The size of tensor a (65536) must match the size of tensor b (64) at non-singleton dimension 3
[2m[36m(func pid=96433)[0m Exception in thread Thread-3:
[2m[36m(func pid=96433)[0m Traceback (most recent call last):
[2m[36m(func pid=96433)[0m   File "/opt/apps/apps/python/miniconda3/4.10.3/lib/python3.9/threading.py", line 954, in _bootstrap_inner
[2m[36m(func pid=96433)[0m     self.run()
[2m[36m(func pid=96433)[0m   File "/mnt/iusers01/ct01/t18155cb/.local/lib/python3.9/site-packages/ray/tune/function_runner.py", line 298, in run
[2m[36m(func pid=96433)[0m     raise e
[2m[36m(func pid=96433)[0m   File "/mnt/iusers01/ct01/t18155cb/.local/lib/python3.9/site-packages/ray/tune/function_runner.py", line 272, in run
[2m[36m(func pid=96433)[0m     self._entrypoint()
[2m[36m(func pid=96433)[0m   File "/mnt/iusers01/ct01/t18155cb/.local/lib/python3.9/site-packages/ray/tune/function_runner.py", line 348, in entrypoint
[2m[36m(func pid=96433)[0m     return self._trainable_func(
[2m[36m(func pid=96433)[0m   File "/mnt/iusers01/ct01/t18155cb/.local/lib/python3.9/site-packages/ray/util/tracing/tracing_helper.py", line 462, in _resume_span
[2m[36m(func pid=96433)[0m     return method(self, *_args, **_kwargs)
[2m[36m(func pid=96433)[0m   File "/mnt/iusers01/ct01/t18155cb/.local/lib/python3.9/site-packages/ray/tune/function_runner.py", line 640, in _trainable_func
[2m[36m(func pid=96433)[0m     output = fn()
[2m[36m(func pid=96433)[0m   File "/net/scratch2/t18155cb/SwinVisonTranslation_mIHC/Ray_tune_hyp.py", line 90, in train_model
[2m[36m(func pid=96433)[0m     outputs = model(inputs)
[2m[36m(func pid=96433)[0m   File "/mnt/iusers01/ct01/t18155cb/.local/lib/python3.9/site-packages/torch/nn/modules/module.py", line 1501, in _call_impl
[2m[36m(func pid=96433)[0m     return forward_call(*args, **kwargs)
[2m[36m(func pid=96433)[0m   File "/net/scratch2/t18155cb/SwinVisonTranslation_mIHC/SwinVisionTranformer.py", line 106, in forward
[2m[36m(func pid=96433)[0m     x = x + x_skip
[2m[36m(func pid=96433)[0m RuntimeError: The size of tensor a (65536) must match the size of tensor b (64) at non-singleton dimension 3
2023-04-18 23:14:46,516	ERROR trial_runner.py:876 -- Trial train_model_99452_00011: Error processing event.
NoneType: None
2023-04-18 23:14:47,437	INFO trial_runner.py:803 -- starting train_model_99452_00015
[2m[36m(func pid=103423)[0m /mnt/iusers01/ct01/t18155cb/.local/lib/python3.9/site-packages/torch/functional.py:504: UserWarning: torch.meshgrid: in an upcoming release, it will be required to pass the indexing argument. (Triggered internally at ../aten/src/ATen/native/TensorShape.cpp:3483.)
[2m[36m(func pid=103423)[0m   return _VF.meshgrid(tensors, **kwargs)  # type: ignore[attr-defined]
[2m[36m(func pid=103423)[0m /mnt/iusers01/ct01/t18155cb/.local/lib/python3.9/site-packages/torch/cuda/amp/grad_scaler.py:120: UserWarning: torch.cuda.amp.GradScaler is enabled, but CUDA is not available.  Disabling.
[2m[36m(func pid=103423)[0m   warnings.warn("torch.cuda.amp.GradScaler is enabled, but CUDA is not available.  Disabling.")
[2m[36m(func pid=103423)[0m /mnt/iusers01/ct01/t18155cb/.local/lib/python3.9/site-packages/torch/amp/autocast_mode.py:204: UserWarning: User provided device_type of 'cuda', but CUDA is not available. Disabling
[2m[36m(func pid=103423)[0m   warnings.warn('User provided device_type of \'cuda\', but CUDA is not available. Disabling')
[2m[36m(func pid=102847)[0m 2023-04-18 23:40:20,584	ERROR function_runner.py:281 -- Runner Thread raised error.
[2m[36m(func pid=102847)[0m Traceback (most recent call last):
[2m[36m(func pid=102847)[0m   File "/mnt/iusers01/ct01/t18155cb/.local/lib/python3.9/site-packages/ray/tune/function_runner.py", line 272, in run
[2m[36m(func pid=102847)[0m     self._entrypoint()
[2m[36m(func pid=102847)[0m   File "/mnt/iusers01/ct01/t18155cb/.local/lib/python3.9/site-packages/ray/tune/function_runner.py", line 348, in entrypoint
[2m[36m(func pid=102847)[0m     return self._trainable_func(
[2m[36m(func pid=102847)[0m   File "/mnt/iusers01/ct01/t18155cb/.local/lib/python3.9/site-packages/ray/util/tracing/tracing_helper.py", line 462, in _resume_span
[2m[36m(func pid=102847)[0m     return method(self, *_args, **_kwargs)
[2m[36m(func pid=102847)[0m   File "/mnt/iusers01/ct01/t18155cb/.local/lib/python3.9/site-packages/ray/tune/function_runner.py", line 640, in _trainable_func
[2m[36m(func pid=102847)[0m     output = fn()
[2m[36m(func pid=102847)[0m   File "/net/scratch2/t18155cb/SwinVisonTranslation_mIHC/Ray_tune_hyp.py", line 90, in train_model
[2m[36m(func pid=102847)[0m     outputs = model(inputs)
[2m[36m(func pid=102847)[0m   File "/mnt/iusers01/ct01/t18155cb/.local/lib/python3.9/site-packages/torch/nn/modules/module.py", line 1501, in _call_impl
[2m[36m(func pid=102847)[0m     return forward_call(*args, **kwargs)
[2m[36m(func pid=102847)[0m   File "/net/scratch2/t18155cb/SwinVisonTranslation_mIHC/SwinVisionTranformer.py", line 106, in forward
[2m[36m(func pid=102847)[0m     x = x + x_skip
[2m[36m(func pid=102847)[0m RuntimeError: The size of tensor a (65536) must match the size of tensor b (64) at non-singleton dimension 3
[2m[36m(func pid=102847)[0m Exception in thread Thread-3:
[2m[36m(func pid=102847)[0m Traceback (most recent call last):
[2m[36m(func pid=102847)[0m   File "/opt/apps/apps/python/miniconda3/4.10.3/lib/python3.9/threading.py", line 954, in _bootstrap_inner
[2m[36m(func pid=102847)[0m     self.run()
[2m[36m(func pid=102847)[0m   File "/mnt/iusers01/ct01/t18155cb/.local/lib/python3.9/site-packages/ray/tune/function_runner.py", line 298, in run
[2m[36m(func pid=102847)[0m     raise e
[2m[36m(func pid=102847)[0m   File "/mnt/iusers01/ct01/t18155cb/.local/lib/python3.9/site-packages/ray/tune/function_runner.py", line 272, in run
[2m[36m(func pid=102847)[0m     self._entrypoint()
[2m[36m(func pid=102847)[0m   File "/mnt/iusers01/ct01/t18155cb/.local/lib/python3.9/site-packages/ray/tune/function_runner.py", line 348, in entrypoint
[2m[36m(func pid=102847)[0m     return self._trainable_func(
[2m[36m(func pid=102847)[0m   File "/mnt/iusers01/ct01/t18155cb/.local/lib/python3.9/site-packages/ray/util/tracing/tracing_helper.py", line 462, in _resume_span
[2m[36m(func pid=102847)[0m     return method(self, *_args, **_kwargs)
[2m[36m(func pid=102847)[0m   File "/mnt/iusers01/ct01/t18155cb/.local/lib/python3.9/site-packages/ray/tune/function_runner.py", line 640, in _trainable_func
[2m[36m(func pid=102847)[0m     output = fn()
[2m[36m(func pid=102847)[0m   File "/net/scratch2/t18155cb/SwinVisonTranslation_mIHC/Ray_tune_hyp.py", line 90, in train_model
[2m[36m(func pid=102847)[0m     outputs = model(inputs)
[2m[36m(func pid=102847)[0m   File "/mnt/iusers01/ct01/t18155cb/.local/lib/python3.9/site-packages/torch/nn/modules/module.py", line 1501, in _call_impl
[2m[36m(func pid=102847)[0m     return forward_call(*args, **kwargs)
[2m[36m(func pid=102847)[0m   File "/net/scratch2/t18155cb/SwinVisonTranslation_mIHC/SwinVisionTranformer.py", line 106, in forward
[2m[36m(func pid=102847)[0m     x = x + x_skip
[2m[36m(func pid=102847)[0m RuntimeError: The size of tensor a (65536) must match the size of tensor b (64) at non-singleton dimension 3
2023-04-18 23:40:25,677	ERROR trial_runner.py:876 -- Trial train_model_99452_00014: Error processing event.
NoneType: None
2023-04-18 23:40:26,538	INFO trial_runner.py:803 -- starting train_model_99452_00016
[2m[36m(func pid=106512)[0m /mnt/iusers01/ct01/t18155cb/.local/lib/python3.9/site-packages/torch/functional.py:504: UserWarning: torch.meshgrid: in an upcoming release, it will be required to pass the indexing argument. (Triggered internally at ../aten/src/ATen/native/TensorShape.cpp:3483.)
[2m[36m(func pid=106512)[0m   return _VF.meshgrid(tensors, **kwargs)  # type: ignore[attr-defined]
[2m[36m(func pid=106512)[0m /mnt/iusers01/ct01/t18155cb/.local/lib/python3.9/site-packages/torch/cuda/amp/grad_scaler.py:120: UserWarning: torch.cuda.amp.GradScaler is enabled, but CUDA is not available.  Disabling.
[2m[36m(func pid=106512)[0m   warnings.warn("torch.cuda.amp.GradScaler is enabled, but CUDA is not available.  Disabling.")
[2m[36m(func pid=106512)[0m /mnt/iusers01/ct01/t18155cb/.local/lib/python3.9/site-packages/torch/amp/autocast_mode.py:204: UserWarning: User provided device_type of 'cuda', but CUDA is not available. Disabling
[2m[36m(func pid=106512)[0m   warnings.warn('User provided device_type of \'cuda\', but CUDA is not available. Disabling')
[2m[36m(func pid=94504)[0m 2023-04-18 23:44:41,859	ERROR function_runner.py:281 -- Runner Thread raised error.
[2m[36m(func pid=94504)[0m Traceback (most recent call last):
[2m[36m(func pid=94504)[0m   File "/mnt/iusers01/ct01/t18155cb/.local/lib/python3.9/site-packages/ray/tune/function_runner.py", line 272, in run
[2m[36m(func pid=94504)[0m     self._entrypoint()
[2m[36m(func pid=94504)[0m   File "/mnt/iusers01/ct01/t18155cb/.local/lib/python3.9/site-packages/ray/tune/function_runner.py", line 348, in entrypoint
[2m[36m(func pid=94504)[0m     return self._trainable_func(
[2m[36m(func pid=94504)[0m   File "/mnt/iusers01/ct01/t18155cb/.local/lib/python3.9/site-packages/ray/util/tracing/tracing_helper.py", line 462, in _resume_span
[2m[36m(func pid=94504)[0m     return method(self, *_args, **_kwargs)
[2m[36m(func pid=94504)[0m   File "/mnt/iusers01/ct01/t18155cb/.local/lib/python3.9/site-packages/ray/tune/function_runner.py", line 640, in _trainable_func
[2m[36m(func pid=94504)[0m     output = fn()
[2m[36m(func pid=94504)[0m   File "/net/scratch2/t18155cb/SwinVisonTranslation_mIHC/Ray_tune_hyp.py", line 90, in train_model
[2m[36m(func pid=94504)[0m     outputs = model(inputs)
[2m[36m(func pid=94504)[0m   File "/mnt/iusers01/ct01/t18155cb/.local/lib/python3.9/site-packages/torch/nn/modules/module.py", line 1501, in _call_impl
[2m[36m(func pid=94504)[0m     return forward_call(*args, **kwargs)
[2m[36m(func pid=94504)[0m   File "/net/scratch2/t18155cb/SwinVisonTranslation_mIHC/SwinVisionTranformer.py", line 105, in forward
[2m[36m(func pid=94504)[0m     x = self.decoder(x)
[2m[36m(func pid=94504)[0m   File "/mnt/iusers01/ct01/t18155cb/.local/lib/python3.9/site-packages/torch/nn/modules/module.py", line 1501, in _call_impl
[2m[36m(func pid=94504)[0m     return forward_call(*args, **kwargs)
[2m[36m(func pid=94504)[0m   File "/mnt/iusers01/ct01/t18155cb/.local/lib/python3.9/site-packages/torch/nn/modules/container.py", line 217, in forward
[2m[36m(func pid=94504)[0m     input = module(input)
[2m[36m(func pid=94504)[0m   File "/mnt/iusers01/ct01/t18155cb/.local/lib/python3.9/site-packages/torch/nn/modules/module.py", line 1501, in _call_impl
[2m[36m(func pid=94504)[0m     return forward_call(*args, **kwargs)
[2m[36m(func pid=94504)[0m   File "/mnt/iusers01/ct01/t18155cb/.local/lib/python3.9/site-packages/torch/nn/modules/upsampling.py", line 156, in forward
[2m[36m(func pid=94504)[0m     return F.interpolate(input, self.size, self.scale_factor, self.mode, self.align_corners,
[2m[36m(func pid=94504)[0m   File "/mnt/iusers01/ct01/t18155cb/.local/lib/python3.9/site-packages/torch/nn/functional.py", line 3959, in interpolate
[2m[36m(func pid=94504)[0m     return torch._C._nn.upsample_bilinear2d(input, output_size, align_corners, scale_factors)
[2m[36m(func pid=94504)[0m RuntimeError: [enforce fail at alloc_cpu.cpp:75] err == 0. DefaultCPUAllocator: can't allocate memory: you tried to allocate 274877906944 bytes. Error code 12 (Cannot allocate memory)
[2m[36m(func pid=94504)[0m Exception in thread Thread-3:
[2m[36m(func pid=94504)[0m Traceback (most recent call last):
[2m[36m(func pid=94504)[0m   File "/opt/apps/apps/python/miniconda3/4.10.3/lib/python3.9/threading.py", line 954, in _bootstrap_inner
[2m[36m(func pid=94504)[0m     self.run()
[2m[36m(func pid=94504)[0m   File "/mnt/iusers01/ct01/t18155cb/.local/lib/python3.9/site-packages/ray/tune/function_runner.py", line 298, in run
[2m[36m(func pid=94504)[0m     raise e
[2m[36m(func pid=94504)[0m   File "/mnt/iusers01/ct01/t18155cb/.local/lib/python3.9/site-packages/ray/tune/function_runner.py", line 272, in run
[2m[36m(func pid=94504)[0m     self._entrypoint()
[2m[36m(func pid=94504)[0m   File "/mnt/iusers01/ct01/t18155cb/.local/lib/python3.9/site-packages/ray/tune/function_runner.py", line 348, in entrypoint
[2m[36m(func pid=94504)[0m     return self._trainable_func(
[2m[36m(func pid=94504)[0m   File "/mnt/iusers01/ct01/t18155cb/.local/lib/python3.9/site-packages/ray/util/tracing/tracing_helper.py", line 462, in _resume_span
[2m[36m(func pid=94504)[0m     return method(self, *_args, **_kwargs)
[2m[36m(func pid=94504)[0m   File "/mnt/iusers01/ct01/t18155cb/.local/lib/python3.9/site-packages/ray/tune/function_runner.py", line 640, in _trainable_func
[2m[36m(func pid=94504)[0m     output = fn()
[2m[36m(func pid=94504)[0m   File "/net/scratch2/t18155cb/SwinVisonTranslation_mIHC/Ray_tune_hyp.py", line 90, in train_model
[2m[36m(func pid=94504)[0m     outputs = model(inputs)
[2m[36m(func pid=94504)[0m   File "/mnt/iusers01/ct01/t18155cb/.local/lib/python3.9/site-packages/torch/nn/modules/module.py", line 1501, in _call_impl
[2m[36m(func pid=94504)[0m     return forward_call(*args, **kwargs)
[2m[36m(func pid=94504)[0m   File "/net/scratch2/t18155cb/SwinVisonTranslation_mIHC/SwinVisionTranformer.py", line 105, in forward
[2m[36m(func pid=94504)[0m     x = self.decoder(x)
[2m[36m(func pid=94504)[0m   File "/mnt/iusers01/ct01/t18155cb/.local/lib/python3.9/site-packages/torch/nn/modules/module.py", line 1501, in _call_impl
[2m[36m(func pid=94504)[0m     return forward_call(*args, **kwargs)
[2m[36m(func pid=94504)[0m   File "/mnt/iusers01/ct01/t18155cb/.local/lib/python3.9/site-packages/torch/nn/modules/container.py", line 217, in forward
[2m[36m(func pid=94504)[0m     input = module(input)
[2m[36m(func pid=94504)[0m   File "/mnt/iusers01/ct01/t18155cb/.local/lib/python3.9/site-packages/torch/nn/modules/module.py", line 1501, in _call_impl
[2m[36m(func pid=94504)[0m     return forward_call(*args, **kwargs)
[2m[36m(func pid=94504)[0m   File "/mnt/iusers01/ct01/t18155cb/.local/lib/python3.9/site-packages/torch/nn/modules/upsampling.py", line 156, in forward
[2m[36m(func pid=94504)[0m     return F.interpolate(input, self.size, self.scale_factor, self.mode, self.align_corners,
[2m[36m(func pid=94504)[0m   File "/mnt/iusers01/ct01/t18155cb/.local/lib/python3.9/site-packages/torch/nn/functional.py", line 3959, in interpolate
[2m[36m(func pid=94504)[0m     return torch._C._nn.upsample_bilinear2d(input, output_size, align_corners, scale_factors)
[2m[36m(func pid=94504)[0m RuntimeError: [enforce fail at alloc_cpu.cpp:75] err == 0. DefaultCPUAllocator: can't allocate memory: you tried to allocate 274877906944 bytes. Error code 12 (Cannot allocate memory)
2023-04-18 23:44:42,255	ERROR trial_runner.py:876 -- Trial train_model_99452_00008: Error processing event.
NoneType: None
2023-04-18 23:44:42,550	INFO trial_runner.py:803 -- starting train_model_99452_00017
[2m[36m(func pid=107107)[0m /mnt/iusers01/ct01/t18155cb/.local/lib/python3.9/site-packages/torch/functional.py:504: UserWarning: torch.meshgrid: in an upcoming release, it will be required to pass the indexing argument. (Triggered internally at ../aten/src/ATen/native/TensorShape.cpp:3483.)
[2m[36m(func pid=107107)[0m   return _VF.meshgrid(tensors, **kwargs)  # type: ignore[attr-defined]
[2m[36m(func pid=107107)[0m /mnt/iusers01/ct01/t18155cb/.local/lib/python3.9/site-packages/torch/cuda/amp/grad_scaler.py:120: UserWarning: torch.cuda.amp.GradScaler is enabled, but CUDA is not available.  Disabling.
[2m[36m(func pid=107107)[0m   warnings.warn("torch.cuda.amp.GradScaler is enabled, but CUDA is not available.  Disabling.")
[2m[36m(func pid=107107)[0m /mnt/iusers01/ct01/t18155cb/.local/lib/python3.9/site-packages/torch/amp/autocast_mode.py:204: UserWarning: User provided device_type of 'cuda', but CUDA is not available. Disabling
[2m[36m(func pid=107107)[0m   warnings.warn('User provided device_type of \'cuda\', but CUDA is not available. Disabling')
